Workbook
Name pp: '2015'!$B$1:$U$39
Name pp: '2015~2018'!$B$1:$U$7
Name pp: '2016'!$B$1:$U$39
Name pp: '2017'!$B$1:$U$39
Name pp: '2018'!$B$1:$U$39

Sheet 歷年(2021~)
A1: 性侵害事件通報被害及嫌疑人概況 Overview of Victim and Offender Status in Reporting Sexual Assault Cases
A3: 單位：人 unit:Person
A4: 年 別 | C4: 性別 | D4: 性侵害被害人統計 Statistics of Sexual Assault Victims | AG4: 性侵害嫌疑人年齡統計 Statistics of Age of Sexual Assault Offenders
D5: 國籍、身分別 By Nationality and Identity | K5: 年齡別 By Age | V5: 身心障礙別 By Disability | AG5: 年齡別 By Age
D6: 合計 | E6: 本國籍 非原住民 | F6: 本國籍 原住民 | G6: 大陸及 港澳籍 | H6: 外國籍 | I6: 無國籍 | J6: 資料 不明 | K6: 合計 | L6: 0-未滿6歲 | M6: 6-未滿12歲 | N6: 12-未滿18歲 | O6: 18-未滿24歲 | P6: 24-未滿30歲 | Q6: 30-未滿40歲 | R6: 40-未滿50歲 | S6: 50-未滿65歲 | T6: 65歲 以上 | U6: 不詳 | V6: 合計 | W6: 非身心 障礙 | X6: 智障 | Y6: 視障 | Z6: 精神 病患 | AA6: 聲(語)障 | AB6: 聽障 | AC6: 肢障 | AD6: 多重 障礙 | AE6: 其他 障礙 | AF6: 不詳 | AG6: 合計 | AH6: 0-未滿6歲 | AI6: 6-未滿12歲 | AJ6: 12-未滿18歲 | AK6: 18-未滿24歲 | AL6: 24-未滿30歲 | AM6: 30-未滿40歲 | AN6: 40-未滿50歲 | AO6: 50-未滿65歲 | AP6: 65歲 以上 | AQ6: 不詳
A7: Year | C7: Gender | D7: Total | E7: Non-Indigenous Native | F7: Indigenous Native | G7: Mainland China and Hong Kong and Macau | H7: Foreign | I7: Stateless | J7: Unknown Information | K7: Total | L7: Under 6 Years | M7: 6-Under 12 Years | N7: 12-Under 18 Years | O7: 18-Under 24 Years | P7: 24-Under 30 Years | Q7: 30-Under 40 Years | R7: 40-Under 50 Years | S7: 50-Under 65 Years | T7: Above 65 Years | U7: Unknown | V7: Total | W7: Not Disability | X7: Intellectually Disabled | Y7: Vision | Z7: Mentally Illed | AA7: Voice | AB7: Hearing | AC7: Physically Impaired | AD7: Multiple | AE7: Other | AF7: Unknown | AG7: Total | AH7: Under 6 Years | AI7: 6-Under 12 Years | AJ7: 12-Under 18 Years | AK7: 18-Under 2 Years | AL7: 24-Under 30 Years | AM7: 30-Under 40 Years | AN7: 40-Under 50 Years | AO7: 50-Under 65 Years | AP7: Above 65 Years | AQ7: Unknown
A8: 110年 2021 | C8: 計 Total | D8: 7787 | E8: 6787 | F8: 680 | G8: 26 | H8: 129 | I8: 2 | J8: 163 | K8: 7787 | L8: 210 | M8: 630 | N8: 3680 | O8: 1135 | P8: 677 | Q8: 778 | R8: 427 | S8: 173 | T8: 53 | U8: 24 | V8: 7787 | W8: 6775 | X8: 354 | Y8: 6 | Z8: 213 | AA8: 4 | AB8: 16 | AC8: 22 | AD8: 72 | AE8: 43 | AF8: 282 | AG8: 7258 | AH8: 16 | AI8: 148 | AJ8: 1720 | AK8: 939 | AL8: 479 | AM8: 664 | AN8: 645 | AO8: 495 | AP8: 189 | AQ8: 1963
C9: 男 Male | D9: 1351 | E9: 1138 | F9: 161 | G9: 2 | H9: 15 | I9: 1 | J9: 34 | K9: 1351 | L9: 45 | M9: 185 | N9: 879 | O9: 96 | P9: 56 | Q9: 44 | R9: 34 | S9: 8 | T9: 3 | U9: 1 | V9: 1351 | W9: 1178 | X9: 59 | Y9: 0 | Z9: 16 | AA9: 0 | AB9: 2 | AC9: 0 | AD9: 13 | AE9: 11 | AF9: 72 | AG9: 6316 | AH9: 16 | AI9: 117 | AJ9: 1183 | AK9: 892 | AL9: 468 | AM9: 652 | AN9: 614 | AO9: 488 | AP9: 185 | AQ9: 1701
C10: 女 Female | D10: 6406 | E10: 5623 | F10: 519 | G10: 24 | H10: 114 | I10: 1 | J10: 125 | K10: 6406 | L10: 165 | M10: 441 | N10: 2784 | O10: 1037 | P10: 618 | Q10: 733 | R10: 392 | S10: 164 | T10: 50 | U10: 22 | V10: 6406 | W10: 5571 | X10: 295 | Y10: 6 | Z10: 196 | AA10: 4 | AB10: 14 | AC10: 22 | AD10: 58 | AE10: 32 | AF10: 208 | AG10: 736 | AH10: 0 | AI10: 31 | AJ10: 525 | AK10: 40 | AL10: 10 | AM10: 11 | AN10: 30 | AO10: 7 | AP10: 4 | AQ10: 78
C11: 其他 Other | D11: 2 | E11: 2 | F11: 0 | G11: 0 | H11: 0 | I11: 0 | J11: 0 | K11: 2 | L11: 0 | M11: 0 | N11: 0 | O11: 0 | P11: 2 | Q11: 0 | R11: 0 | S11: 0 | T11: 0 | U11: 0 | V11: 2 | W11: 1 | X11: 0 | Y11: 0 | Z11: 1 | AA11: 0 | AB11: 0 | AC11: 0 | AD11: 0 | AE11: 0 | AF11: 0 | AG11: 0 | AH11: 0 | AI11: 0 | AJ11: 0 | AK11: 0 | AL11: 0 | AM11: 0 | AN11: 0 | AO11: 0 | AP11: 0 | AQ11: 0
C12: 不詳Unknown | D12: 28 | E12: 24 | F12: 0 | G12: 0 | H12: 0 | I12: 0 | J12: 4 | K12: 28 | L12: 0 | M12: 4 | N12: 17 | O12: 2 | P12: 1 | Q12: 1 | R12: 1 | S12: 1 | T12: 0 | U12: 1 | V12: 28 | W12: 25 | X12: 0 | Y12: 0 | Z12: 0 | AA12: 0 | AB12: 0 | AC12: 0 | AD12: 1 | AE12: 0 | AF12: 2 | AG12: 206 | AH12: 0 | AI12: 0 | AJ12: 12 | AK12: 7 | AL12: 1 | AM12: 1 | AN12: 1 | AO12: 0 | AP12: 0 | AQ12: 184
A13: 111年 2022 | C13: 計 Total | D13: 8401 | E13: 7357 | F13: 765 | G13: 29 | H13: 109 | I13: 0 | J13: 141 | K13: 8401 | L13: 203 | M13: 608 | N13: 3998 | O13: 1216 | P13: 763 | Q13: 831 | R13: 489 | S13: 218 | T13: 50 | U13: 25 | V13: 8401 | W13: 7402 | X13: 364 | Y13: 8 | Z13: 265 | AA13: 5 | AB13: 24 | AC13: 32 | AD13: 64 | AE13: 98 | AF13: 139 | AG13: 7865 | AH13: 11 | AI13: 168 | AJ13: 1953 | AK13: 1000 | AL13: 545 | AM13: 719 | AN13: 658 | AO13: 537 | AP13: 209 | AQ13: 2065
C14: 男 Male | D14: 1383 | E14: 1173 | F14: 173 | G14: 1 | H14: 9 | I14: 0 | J14: 27 | K14: 1383 | L14: 35 | M14: 157 | N14: 950 | O14: 93 | P14: 53 | Q14: 53 | R14: 20 | S14: 16 | T14: 5 | U14: 1 | V14: 1383 | W14: 1214 | X14: 66 | Y14: 1 | Z14: 26 | AA14: 1 | AB14: 4 | AC14: 5 | AD14: 13 | AE14: 26 | AF14: 27 | AG14: 6874 | AH14: 6 | AI14: 127 | AJ14: 1398 | AK14: 949 | AL14: 536 | AM14: 693 | AN14: 636 | AO14: 525 | AP14: 206 | AQ14: 1798
C15: 女 Female | D15: 6982 | E15: 6161 | F15: 586 | G15: 28 | H15: 100 | I15: 0 | J15: 107 | K15: 6982 | L15: 167 | M15: 450 | N15: 3023 | O15: 1119 | P15: 709 | Q15: 776 | R15: 469 | S15: 202 | T15: 45 | U15: 22 | V15: 6982 | W15: 6162 | X15: 298 | Y15: 7 | Z15: 238 | AA15: 4 | AB15: 20 | AC15: 27 | AD15: 50 | AE15: 71 | AF15: 105 | AG15: 783 | AH15: 5 | AI15: 40 | AJ15: 544 | AK15: 46 | AL15: 8 | AM15: 26 | AN15: 22 | AO15: 11 | AP15: 3 | AQ15: 78
C16: 其他 Other | D16: 3 | E16: 2 | F16: 1 | G16: 0 | H16: 0 | I16: 0 | J16: 0 | K16: 3 | L16: 0 | M16: 0 | N16: 0 | O16: 2 | P16: 1 | Q16: 0 | R16: 0 | S16: 0 | T16: 0 | U16: 0 | V16: 3 | W16: 3 | X16: 0 | Y16: 0 | Z16: 0 | AA16: 0 | AB16: 0 | AC16: 0 | AD16: 0 | AE16: 0 | AF16: 0 | AG16: 0 | AH16: 0 | AI16: 0 | AJ16: 0 | AK16: 0 | AL16: 0 | AM16: 0 | AN16: 0 | AO16: 0 | AP16: 0 | AQ16: 0
C17: 不詳Unknown | D17: 33 | E17: 21 | F17: 5 | G17: 0 | H17: 0 | I17: 0 | J17: 7 | K17: 33 | L17: 1 | M17: 1 | N17: 25 | O17: 2 | P17: 0 | Q17: 2 | R17: 0 | S17: 0 | T17: 0 | U17: 2 | V17: 33 | W17: 23 | X17: 0 | Y17: 0 | Z17: 1 | AA17: 0 | AB17: 0 | AC17: 0 | AD17: 1 | AE17: 1 | AF17: 7 | AG17: 208 | AH17: 0 | AI17: 1 | AJ17: 11 | AK17: 5 | AL17: 1 | AM17: 0 | AN17: 0 | AO17: 1 | AP17: 0 | AQ17: 189
A18: 112年 2023 | C18: 計 Total | D18: 9413 | E18: 8241 | F18: 813 | G18: 31 | H18: 119 | I18: 0 | J18: 209 | K18: 9413 | L18: 206 | M18: 767 | N18: 4182 | O18: 1323 | P18: 890 | Q18: 1039 | R18: 627 | S18: 256 | T18: 82 | U18: 41 | V18: 9413 | W18: 8301 | X18: 400 | Y18: 17 | Z18: 299 | AA18: 6 | AB18: 18 | AC18: 39 | AD18: 101 | AE18: 101 | AF18: 131 | AG18: 8731 | AH18: 27 | AI18: 168 | AJ18: 2080 | AK18: 1038 | AL18: 564 | AM18: 826 | AN18: 768 | AO18: 637 | AP18: 288 | AQ18: 2335
C19: 男 Male | D19: 1665 | E19: 1442 | F19: 176 | G19: 3 | H19: 10 | I19: 0 | J19: 34 | K19: 1665 | L19: 31 | M19: 230 | N19: 1032 | O19: 135 | P19: 83 | Q19: 86 | R19: 42 | S19: 15 | T19: 6 | U19: 5 | V19: 1665 | W19: 1500 | X19: 63 | Y19: 1 | Z19: 36 | AA19: 0 | AB19: 1 | AC19: 3 | AD19: 18 | AE19: 26 | AF19: 17 | AG19: 7600 | AH19: 21 | AI19: 137 | AJ19: 1435 | AK19: 990 | AL19: 555 | AM19: 798 | AN19: 732 | AO19: 621 | AP19: 285 | AQ19: 2026
C20: 女 Female | D20: 7698 | E20: 6774 | F20: 632 | G20: 27 | H20: 108 | I20: 0 | J20: 157 | K20: 7698 | L20: 175 | M20: 532 | N20: 3122 | O20: 1185 | P20: 804 | Q20: 948 | R20: 582 | S20: 241 | T20: 76 | U20: 33 | V20: 7698 | W20: 6766 | X20: 335 | Y20: 16 | Z20: 263 | AA20: 5 | AB20: 17 | AC20: 36 | AD20: 83 | AE20: 75 | AF20: 102 | AG20: 883 | AH20: 5 | AI20: 31 | AJ20: 634 | AK20: 45 | AL20: 9 | AM20: 24 | AN20: 35 | AO20: 15 | AP20: 3 | AQ20: 82
C21: 其他 Other | D21: 4 | E21: 4 | F21: 0 | G21: 0 | H21: 0 | I21: 0 | J21: 0 | K21: 4 | L21: 0 | M21: 1 | N21: 1 | O21: 2 | P21: 0 | Q21: 0 | R21: 0 | S21: 0 | T21: 0 | U21: 0 | V21: 4 | W21: 4 | X21: 0 | Y21: 0 | Z21: 0 | AA21: 0 | AB21: 0 | AC21: 0 | AD21: 0 | AE21: 0 | AF21: 0 | AG21: 0 | AH21: 0 | AI21: 0 | AJ21: 0 | AK21: 0 | AL21: 0 | AM21: 0 | AN21: 0 | AO21: 0 | AP21: 0 | AQ21: 0
C22: 不詳Unknown | D22: 46 | E22: 21 | F22: 5 | G22: 1 | H22: 1 | I22: 0 | J22: 18 | K22: 46 | L22: 0 | M22: 4 | N22: 27 | O22: 1 | P22: 3 | Q22: 5 | R22: 3 | S22: 0 | T22: 0 | U22: 3 | V22: 46 | W22: 31 | X22: 2 | Y22: 0 | Z22: 0 | AA22: 1 | AB22: 0 | AC22: 0 | AD22: 0 | AE22: 0 | AF22: 12 | AG22: 248 | AH22: 1 | AI22: 0 | AJ22: 11 | AK22: 3 | AL22: 0 | AM22: 4 | AN22: 1 | AO22: 1 | AP22: 0 | AQ22: 227
A23: 113年 2024 | C23: 計 Total | D23: 9230 | E23: 8138 | F23: 715 | G23: 33 | H23: 169 | I23: 0 | J23: 175 | K23: 9230 | L23: 268 | M23: 830 | N23: 3695 | O23: 1383 | P23: 970 | Q23: 1079 | R23: 631 | S23: 267 | T23: 76 | U23: 31 | V23: 9230 | W23: 8124 | X23: 399 | Y23: 12 | Z23: 312 | AA23: 12 | AB23: 29 | AC23: 37 | AD23: 98 | AE23: 109 | AF23: 98 | AG23: 8471 | AH23: 19 | AI23: 195 | AJ23: 1702 | AK23: 999 | AL23: 615 | AM23: 853 | AN23: 781 | AO23: 633 | AP23: 313 | AQ23: 2361
C24: 男 Male | D24: 1612 | E24: 1391 | F24: 164 | G24: 3 | H24: 11 | I24: 0 | J24: 43 | K24: 1612 | L24: 45 | M24: 263 | N24: 877 | O24: 157 | P24: 99 | Q24: 105 | R24: 37 | S24: 21 | T24: 5 | U24: 3 | V24: 1612 | W24: 1414 | X24: 78 | Y24: 2 | Z24: 34 | AA24: 3 | AB24: 5 | AC24: 8 | AD24: 24 | AE24: 34 | AF24: 10 | AG24: 7442 | AH24: 13 | AI24: 154 | AJ24: 1208 | AK24: 944 | AL24: 601 | AM24: 817 | AN24: 745 | AO24: 620 | AP24: 307 | AQ24: 2033
C25: 女 Female | D25: 7572 | E25: 6714 | F25: 547 | G25: 30 | H25: 157 | I25: 0 | J25: 124 | K25: 7572 | L25: 222 | M25: 564 | N25: 2787 | O25: 1224 | P25: 869 | Q25: 968 | R25: 594 | S25: 245 | T25: 71 | U25: 28 | V25: 7572 | W25: 6671 | X25: 320 | Y25: 10 | Z25: 277 | AA25: 9 | AB25: 24 | AC25: 29 | AD25: 72 | AE25: 74 | AF25: 86 | AG25: 790 | AH25: 6 | AI25: 41 | AJ25: 489 | AK25: 48 | AL25: 12 | AM25: 31 | AN25: 34 | AO25: 11 | AP25: 5 | AQ25: 113
C26: 其他 Other | D26: 6 | E26: 4 | F26: 0 | G26: 0 | H26: 1 | I26: 0 | J26: 1 | K26: 6 | L26: 0 | M26: 0 | N26: 1 | O26: 2 | P26: 0 | Q26: 2 | R26: 0 | S26: 1 | T26: 0 | U26: 0 | V26: 6 | W26: 4 | X26: 0 | Y26: 0 | Z26: 1 | AA26: 0 | AB26: 0 | AC26: 0 | AD26: 0 | AE26: 0 | AF26: 1 | AG26: 0 | AH26: 0 | AI26: 0 | AJ26: 0 | AK26: 0 | AL26: 0 | AM26: 0 | AN26: 0 | AO26: 0 | AP26: 0 | AQ26: 0
C27: 不詳Unknown | D27: 40 | E27: 29 | F27: 4 | G27: 0 | H27: 0 | I27: 0 | J27: 7 | K27: 40 | L27: 1 | M27: 3 | N27: 30 | O27: 0 | P27: 2 | Q27: 4 | R27: 0 | S27: 0 | T27: 0 | U27: 0 | V27: 40 | W27: 35 | X27: 1 | Y27: 0 | Z27: 0 | AA27: 0 | AB27: 0 | AC27: 0 | AD27: 2 | AE27: 1 | AF27: 1 | AG27: 239 | AH27: 0 | AI27: 0 | AJ27: 5 | AK27: 7 | AL27: 2 | AM27: 5 | AN27: 2 | AO27: 2 | AP27: 1 | AQ27: 215
A28: 113年上半年 Jan.-June ,2024 | C28: 計 Total | D28: 4808 | E28: 4253 | F28: 380 | G28: 12 | H28: 81 | I28: 0 | J28: 82 | K28: 4808 | L28: 119 | M28: 419 | N28: 2054 | O28: 707 | P28: 475 | Q28: 536 | R28: 323 | S28: 131 | T28: 32 | U28: 12 | V28: 4808 | W28: 4250 | X28: 213 | Y28: 9 | Z28: 137 | AA28: 8 | AB28: 9 | AC28: 17 | AD28: 56 | AE28: 52 | AF28: 57 | AG28: 4456 | AH28: 6 | AI28: 97 | AJ28: 958 | AK28: 560 | AL28: 301 | AM28: 423 | AN28: 386 | AO28: 320 | AP28: 162 | AQ28: 1243
C29: 男 Male | D29: 823 | E29: 706 | F29: 97 | G29: 0 | H29: 3 | I29: 0 | J29: 17 | K29: 823 | L29: 25 | M29: 115 | N29: 470 | O29: 85 | P29: 45 | Q29: 49 | R29: 19 | S29: 12 | T29: 2 | U29: 1 | V29: 823 | W29: 729 | X29: 36 | Y29: 1 | Z29: 16 | AA29: 2 | AB29: 1 | AC29: 4 | AD29: 15 | AE29: 15 | AF29: 4 | AG29: 3892 | AH29: 6 | AI29: 70 | AJ29: 659 | AK29: 525 | AL29: 296 | AM29: 407 | AN29: 369 | AO29: 315 | AP29: 159 | AQ29: 1086
C30: 女 Female | D30: 3954 | E30: 3524 | F30: 280 | G30: 12 | H30: 77 | I30: 0 | J30: 61 | K30: 3954 | L30: 94 | M30: 302 | N30: 1564 | O30: 620 | P30: 428 | Q30: 482 | R30: 304 | S30: 119 | T30: 30 | U30: 11 | V30: 3954 | W30: 3495 | X30: 176 | Y30: 8 | Z30: 121 | AA30: 6 | AB30: 8 | AC30: 13 | AD30: 40 | AE30: 36 | AF30: 51 | AG30: 454 | AH30: 0 | AI30: 27 | AJ30: 296 | AK30: 31 | AL30: 5 | AM30: 14 | AN30: 16 | AO30: 5 | AP30: 3 | AQ30: 57
C31: 其他 Other | D31: 5 | E31: 3 | F31: 0 | G31: 0 | H31: 1 | I31: 0 | J31: 1 | K31: 5 | L31: 0 | M31: 0 | N31: 1 | O31: 2 | P31: 0 | Q31: 2 | R31: 0 | S31: 0 | T31: 0 | U31: 0 | V31: 5 | W31: 4 | X31: 0 | Y31: 0 | Z31: 0 | AA31: 0 | AB31: 0 | AC31: 0 | AD31: 0 | AE31: 0 | AF31: 1 | AG31: 0 | AH31: 0 | AI31: 0 | AJ31: 0 | AK31: 0 | AL31: 0 | AM31: 0 | AN31: 0 | AO31: 0 | AP31: 0 | AQ31: 0
C32: 不詳Unknown | D32: 26 | E32: 20 | F32: 3 | G32: 0 | H32: 0 | I32: 0 | J32: 3 | K32: 26 | L32: 0 | M32: 2 | N32: 19 | O32: 0 | P32: 2 | Q32: 3 | R32: 0 | S32: 0 | T32: 0 | U32: 0 | V32: 26 | W32: 22 | X32: 1 | Y32: 0 | Z32: 0 | AA32: 0 | AB32: 0 | AC32: 0 | AD32: 1 | AE32: 1 | AF32: 1 | AG32: 110 | AH32: 0 | AI32: 0 | AJ32: 3 | AK32: 4 | AL32: 0 | AM32: 2 | AN32: 1 | AO32: 0 | AP32: 0 | AQ32: 100
A33: 113年下半年 July-Dec. ,2024 | C33: 計 Total | D33: 4422 | E33: 3885 | F33: 335 | G33: 21 | H33: 88 | I33: 0 | J33: 93 | K33: 4422 | L33: 149 | M33: 411 | N33: 1641 | O33: 676 | P33: 495 | Q33: 543 | R33: 308 | S33: 136 | T33: 44 | U33: 19 | V33: 4422 | W33: 3874 | X33: 186 | Y33: 3 | Z33: 175 | AA33: 4 | AB33: 20 | AC33: 20 | AD33: 42 | AE33: 57 | AF33: 41 | AG33: 4015 | AH33: 13 | AI33: 98 | AJ33: 744 | AK33: 439 | AL33: 314 | AM33: 430 | AN33: 395 | AO33: 313 | AP33: 151 | AQ33: 1118
C34: 男 Male | D34: 789 | E34: 685 | F34: 67 | G34: 3 | H34: 8 | I34: 0 | J34: 26 | K34: 789 | L34: 20 | M34: 148 | N34: 407 | O34: 72 | P34: 54 | Q34: 56 | R34: 18 | S34: 9 | T34: 3 | U34: 2 | V34: 789 | W34: 685 | X34: 42 | Y34: 1 | Z34: 18 | AA34: 1 | AB34: 4 | AC34: 4 | AD34: 9 | AE34: 19 | AF34: 6 | AG34: 3550 | AH34: 7 | AI34: 84 | AJ34: 549 | AK34: 419 | AL34: 305 | AM34: 410 | AN34: 376 | AO34: 305 | AP34: 148 | AQ34: 947
C35: 女 Female | D35: 3618 | E35: 3190 | F35: 267 | G35: 18 | H35: 80 | I35: 0 | J35: 63 | K35: 3618 | L35: 128 | M35: 262 | N35: 1223 | O35: 604 | P35: 441 | Q35: 486 | R35: 290 | S35: 126 | T35: 41 | U35: 17 | V35: 3618 | W35: 3176 | X35: 144 | Y35: 2 | Z35: 156 | AA35: 3 | AB35: 16 | AC35: 16 | AD35: 32 | AE35: 38 | AF35: 35 | AG35: 336 | AH35: 6 | AI35: 14 | AJ35: 193 | AK35: 17 | AL35: 7 | AM35: 17 | AN35: 18 | AO35: 6 | AP35: 2 | AQ35: 56
C36: 其他 Other | D36: 1 | E36: 1 | F36: 0 | G36: 0 | H36: 0 | I36: 0 | J36: 0 | K36: 1 | L36: 0 | M36: 0 | N36: 0 | O36: 0 | P36: 0 | Q36: 0 | R36: 0 | S36: 1 | T36: 0 | U36: 0 | V36: 1 | W36: 0 | X36: 0 | Y36: 0 | Z36: 1 | AA36: 0 | AB36: 0 | AC36: 0 | AD36: 0 | AE36: 0 | AF36: 0 | AG36: 0 | AH36: 0 | AI36: 0 | AJ36: 0 | AK36: 0 | AL36: 0 | AM36: 0 | AN36: 0 | AO36: 0 | AP36: 0 | AQ36: 0
C37: 不詳Unknown | D37: 14 | E37: 9 | F37: 1 | G37: 0 | H37: 0 | I37: 0 | J37: 4 | K37: 14 | L37: 1 | M37: 1 | N37: 11 | O37: 0 | P37: 0 | Q37: 1 | R37: 0 | S37: 0 | T37: 0 | U37: 0 | V37: 14 | W37: 13 | X37: 0 | Y37: 0 | Z37: 0 | AA37: 0 | AB37: 0 | AC37: 0 | AD37: 1 | AE37: 0 | AF37: 0 | AG37: 129 | AH37: 0 | AI37: 0 | AJ37: 2 | AK37: 3 | AL37: 2 | AM37: 3 | AN37: 1 | AO37: 2 | AP37: 1 | AQ37: 115
A38: 114年 2025 | C38: 計 Total | D38: 9565 | E38: 8376 | F38: 761 | G38: 37 | H38: 175 | I38: 1 | J38: 215 | K38: 9565 | L38: 231 | M38: 752 | N38: 3729 | O38: 1439 | P38: 1080 | Q38: 1206 | R38: 697 | S38: 291 | T38: 91 | U38: 49 | V38: 9565 | W38: 8474 | X38: 332 | Y38: 13 | Z38: 316 | AA38: 6 | AB38: 19 | AC38: 51 | AD38: 98 | AE38: 130 | AF38: 126 | AG38: 8768 | AH38: 25 | AI38: 197 | AJ38: 1697 | AK38: 1008 | AL38: 648 | AM38: 907 | AN38: 877 | AO38: 611 | AP38: 308 | AQ38: 2490
C39: 男 Male | D39: 1603 | E39: 1398 | F39: 147 | G39: 5 | H39: 16 | I39: 1 | J39: 36 | K39: 1603 | L39: 44 | M39: 229 | N39: 835 | O39: 162 | P39: 118 | Q39: 130 | R39: 49 | S39: 23 | T39: 6 | U39: 7 | V39: 1603 | W39: 1413 | X39: 54 | Y39: 5 | Z39: 38 | AA39: 1 | AB39: 2 | AC39: 9 | AD39: 24 | AE39: 38 | AF39: 19 | AG39: 7664 | AH39: 23 | AI39: 153 | AJ39: 1187 | AK39: 970 | AL39: 620 | AM39: 867 | AN39: 844 | AO39: 589 | AP39: 296 | AQ39: 2115
C40: 女 Female | D40: 7935 | E40: 6962 | F40: 612 | G40: 32 | H40: 159 | I40: 0 | J40: 170 | K40: 7935 | L40: 187 | M40: 522 | N40: 2877 | O40: 1274 | P40: 961 | Q40: 1075 | R40: 648 | S40: 268 | T40: 85 | U40: 38 | V40: 7935 | W40: 7042 | X40: 278 | Y40: 8 | Z40: 278 | AA40: 5 | AB40: 17 | AC40: 42 | AD40: 74 | AE40: 90 | AF40: 101 | AG40: 828 | AH40: 2 | AI40: 44 | AJ40: 499 | AK40: 37 | AL40: 27 | AM40: 39 | AN40: 30 | AO40: 21 | AP40: 11 | AQ40: 118
C41: 其他 Other | D41: 2 | E41: 2 | F41: 0 | G41: 0 | H41: 0 | I41: 0 | J41: 0 | K41: 2 | L41: 0 | M41: 0 | N41: 0 | O41: 1 | P41: 0 | Q41: 1 | R41: 0 | S41: 0 | T41: 0 | U41: 0 | V41: 2 | W41: 1 | X41: 0 | Y41: 0 | Z41: 0 | AA41: 0 | AB41: 0 | AC41: 0 | AD41: 0 | AE41: 1 | AF41: 0 | AG41: 0 | AH41: 0 | AI41: 0 | AJ41: 0 | AK41: 0 | AL41: 0 | AM41: 0 | AN41: 0 | AO41: 0 | AP41: 0 | AQ41: 0
...

Sheet 2025
A1: 性侵害事件通報被害及嫌疑人概況 Overview of Victim and Offender Status in Reporting Sexual Assault Cases
A2: 114年，2025
A3: 單位：人 unit:Person
A4: 區域別 | C4: 性別 | D4: 性侵害被害人統計 Statistics of Sexual Assault Victims | AG4: 性侵害嫌疑人年齡統計 Statistics of Age of Sexual Assault Offenders
D5: 國籍、身分別 By Nationality and Identity | K5: 年齡別 By Age | V5: 身心障礙別 By Disability | AG5: 年齡別 By Age
D6: 合計 | E6: 本國籍 非原住民 | F6: 本國籍 原住民 | G6: 大陸及 港澳籍 | H6: 外國籍 | I6: 無國籍 | J6: 資料 不明 | K6: 合計 | L6: 0-未滿6歲 | M6: 6-未滿12歲 | N6: 12-未滿18歲 | O6: 18-未滿24歲 | P6: 24-未滿30歲 | Q6: 30-未滿40歲 | R6: 40-未滿50歲 | S6: 50-未滿65歲 | T6: 65歲 以上 | U6: 不詳 | V6: 合計 | W6: 非身心 障礙 | X6: 智障 | Y6: 視障 | Z6: 精神 病患 | AA6: 聲(語)障 | AB6: 聽障 | AC6: 肢障 | AD6: 多重 障礙 | AE6: 其他 障礙 | AF6: 不詳 | AG6: 合計 | AH6: 0-未滿6歲 | AI6: 6-未滿12歲 | AJ6: 12-未滿18歲 | AK6: 18-未滿24歲 | AL6: 24-未滿30歲 | AM6: 30-未滿40歲 | AN6: 40-未滿50歲 | AO6: 50-未滿65歲 | AP6: 65歲 以上 | AQ6: 不詳
A7: Locality | C7: Gender | D7: Total | E7: Non-Indigenous Native | F7: Indigenous Native | G7: Mainland China and Hong Kong and Macau | H7: Foreign | I7: Stateless | J7: Unknown Information | K7: Total | L7: Under 6 Years | M7: 6-Under 12 Years | N7: 12-Under 18 Years | O7: 18-Under 24 Years | P7: 24-Under 30 Years | Q7: 30-Under 40 Years | R7: 40-Under 50 Years | S7: 50-Under 65 Years | T7: Above 65 Years | U7: Unknown | V7: Total | W7: Not Disability | X7: Intellectually Disabled | Y7: Vision | Z7: Mentally Illed | AA7: Voice | AB7: Hearing | AC7: Physically Impaired | AD7: Multiple | AE7: Other | AF7: Unknown | AG7: Total | AH7: Under 6 Years | AI7: 6-Under 12 Years | AJ7: 12-Under 18 Years | AK7: 18-Under 2 Years | AL7: 24-Under 30 Years | AM7: 30-Under 40 Years | AN7: 40-Under 50 Years | AO7: 50-Under 65 Years | AP7: Above 65 Years | AQ7: Unknown
A8: 總計 | C8: 計 Total | D8: 9565 | E8: 8376 | F8: 761 | G8: 37 | H8: 175 | I8: 1 | J8: 215 | K8: 9565 | L8: 231 | M8: 752 | N8: 3729 | O8: 1439 | P8: 1080 | Q8: 1206 | R8: 697 | S8: 291 | T8: 91 | U8: 49 | V8: 9565 | W8: 8474 | X8: 332 | Y8: 13 | Z8: 316 | AA8: 6 | AB8: 19 | AC8: 51 | AD8: 98 | AE8: 130 | AF8: 126 | AG8: 8768 | AH8: 25 | AI8: 197 | AJ8: 1697 | AK8: 1008 | AL8: 648 | AM8: 907 | AN8: 877 | AO8: 611 | AP8: 308 | AQ8: 2490
C9: 男 Male | D9: 1603 | E9: 1398 | F9: 147 | G9: 5 | H9: 16 | I9: 1 | J9: 36 | K9: 1603 | L9: 44 | M9: 229 | N9: 835 | O9: 162 | P9: 118 | Q9: 130 | R9: 49 | S9: 23 | T9: 6 | U9: 7 | V9: 1603 | W9: 1413 | X9: 54 | Y9: 5 | Z9: 38 | AA9: 1 | AB9: 2 | AC9: 9 | AD9: 24 | AE9: 38 | AF9: 19 | AG9: 7664 | AH9: 23 | AI9: 153 | AJ9: 1187 | AK9: 970 | AL9: 620 | AM9: 867 | AN9: 844 | AO9: 589 | AP9: 296 | AQ9: 2115
A10: Total | C10: 女 Female | D10: 7935 | E10: 6962 | F10: 612 | G10: 32 | H10: 159 | I10: 0 | J10: 170 | K10: 7935 | L10: 187 | M10: 522 | N10: 2877 | O10: 1274 | P10: 961 | Q10: 1075 | R10: 648 | S10: 268 | T10: 85 | U10: 38 | V10: 7935 | W10: 7042 | X10: 278 | Y10: 8 | Z10: 278 | AA10: 5 | AB10: 17 | AC10: 42 | AD10: 74 | AE10: 90 | AF10: 101 | AG10: 828 | AH10: 2 | AI10: 44 | AJ10: 499 | AK10: 37 | AL10: 27 | AM10: 39 | AN10: 30 | AO10: 21 | AP10: 11 | AQ10: 118
C11: 其他 Other | D11: 2 | E11: 2 | F11: 0 | G11: 0 | H11: 0 | I11: 0 | J11: 0 | K11: 2 | L11: 0 | M11: 0 | N11: 0 | O11: 1 | P11: 0 | Q11: 1 | R11: 0 | S11: 0 | T11: 0 | U11: 0 | V11: 2 | W11: 1 | X11: 0 | Y11: 0 | Z11: 0 | AA11: 0 | AB11: 0 | AC11: 0 | AD11: 0 | AE11: 1 | AF11: 0 | AG11: 0 | AH11: 0 | AI11: 0 | AJ11: 0 | AK11: 0 | AL11: 0 | AM11: 0 | AN11: 0 | AO11: 0 | AP11: 0 | AQ11: 0
C12: 不詳Unknown | D12: 25 | E12: 14 | F12: 2 | G12: 0 | H12: 0 | I12: 0 | J12: 9 | K12: 25 | L12: 0 | M12: 1 | N12: 17 | O12: 2 | P12: 1 | Q12: 0 | R12: 0 | S12: 0 | T12: 0 | U12: 4 | V12: 25 | W12: 18 | X12: 0 | Y12: 0 | Z12: 0 | AA12: 0 | AB12: 0 | AC12: 0 | AD12: 0 | AE12: 1 | AF12: 6 | AG12: 276 | AH12: 0 | AI12: 0 | AJ12: 11 | AK12: 1 | AL12: 1 | AM12: 1 | AN12: 3 | AO12: 1 | AP12: 1 | AQ12: 257
A13: 新北市 | C13: 計 Total | D13: 1745 | E13: 1568 | F13: 68 | G13: 5 | H13: 25 | I13: 1 | J13: 78 | K13: 1745 | L13: 40 | M13: 138 | N13: 707 | O13: 250 | P13: 217 | Q13: 222 | R13: 98 | S13: 36 | T13: 18 | U13: 19 | V13: 1745 | W13: 1548 | X13: 52 | Y13: 1 | Z13: 55 | AA13: 1 | AB13: 3 | AC13: 9 | AD13: 17 | AE13: 26 | AF13: 33 | AG13: 1615 | AH13: 6 | AI13: 36 | AJ13: 320 | AK13: 163 | AL13: 91 | AM13: 145 | AN13: 152 | AO13: 89 | AP13: 55 | AQ13: 558
C14: 男 Male | D14: 286 | E14: 256 | F14: 15 | G14: 2 | H14: 1 | I14: 1 | J14: 11 | K14: 286 | L14: 7 | M14: 38 | N14: 157 | O14: 28 | P14: 21 | Q14: 20 | R14: 9 | S14: 2 | T14: 1 | U14: 3 | V14: 286 | W14: 246 | X14: 12 | Y14: 1 | Z14: 8 | AA14: 0 | AB14: 0 | AC14: 0 | AD14: 4 | AE14: 9 | AF14: 6 | AG14: 1383 | AH14: 5 | AI14: 26 | AJ14: 215 | AK14: 158 | AL14: 86 | AM14: 137 | AN14: 140 | AO14: 84 | AP14: 51 | AQ14: 481
A15: New Taipei City | C15: 女 Female | D15: 1452 | E15: 1305 | F15: 53 | G15: 3 | H15: 24 | I15: 0 | J15: 67 | K15: 1452 | L15: 33 | M15: 100 | N15: 545 | O15: 221 | P15: 196 | Q15: 201 | R15: 89 | S15: 34 | T15: 17 | U15: 16 | V15: 1452 | W15: 1296 | X15: 40 | Y15: 0 | Z15: 47 | AA15: 1 | AB15: 3 | AC15: 9 | AD15: 13 | AE15: 16 | AF15: 27 | AG15: 186 | AH15: 1 | AI15: 10 | AJ15: 102 | AK15: 5 | AL15: 5 | AM15: 8 | AN15: 11 | AO15: 5 | AP15: 4 | AQ15: 35
C16: 其他 Other | D16: 2 | E16: 2 | F16: 0 | G16: 0 | H16: 0 | I16: 0 | J16: 0 | K16: 2 | L16: 0 | M16: 0 | N16: 0 | O16: 1 | P16: 0 | Q16: 1 | R16: 0 | S16: 0 | T16: 0 | U16: 0 | V16: 2 | W16: 1 | X16: 0 | Y16: 0 | Z16: 0 | AA16: 0 | AB16: 0 | AC16: 0 | AD16: 0 | AE16: 1 | AF16: 0 | AG16: 0 | AH16: 0 | AI16: 0 | AJ16: 0 | AK16: 0 | AL16: 0 | AM16: 0 | AN16: 0 | AO16: 0 | AP16: 0 | AQ16: 0
C17: 不詳Unknown | D17: 5 | E17: 5 | F17: 0 | G17: 0 | H17: 0 | I17: 0 | J17: 0 | K17: 5 | L17: 0 | M17: 0 | N17: 5 | O17: 0 | P17: 0 | Q17: 0 | R17: 0 | S17: 0 | T17: 0 | U17: 0 | V17: 5 | W17: 5 | X17: 0 | Y17: 0 | Z17: 0 | AA17: 0 | AB17: 0 | AC17: 0 | AD17: 0 | AE17: 0 | AF17: 0 | AG17: 46 | AH17: 0 | AI17: 0 | AJ17: 3 | AK17: 0 | AL17: 0 | AM17: 0 | AN17: 1 | AO17: 0 | AP17: 0 | AQ17: 42
A18: 臺北市 | C18: 計 Total | D18: 976 | E18: 888 | F18: 13 | G18: 7 | H18: 32 | I18: 0 | J18: 36 | K18: 976 | L18: 20 | M18: 65 | N18: 225 | O18: 202 | P18: 156 | Q18: 171 | R18: 84 | S18: 29 | T18: 12 | U18: 12 | V18: 976 | W18: 851 | X18: 16 | Y18: 2 | Z18: 33 | AA18: 0 | AB18: 1 | AC18: 8 | AD18: 10 | AE18: 16 | AF18: 39 | AG18: 799 | AH18: 5 | AI18: 22 | AJ18: 84 | AK18: 61 | AL18: 73 | AM18: 73 | AN18: 73 | AO18: 48 | AP18: 26 | AQ18: 334
C19: 男 Male | D19: 153 | E19: 135 | F19: 1 | G19: 2 | H19: 9 | I19: 0 | J19: 6 | K19: 153 | L19: 3 | M19: 25 | N19: 44 | O19: 27 | P19: 20 | Q19: 22 | R19: 5 | S19: 4 | T19: 1 | U19: 2 | V19: 153 | W19: 128 | X19: 2 | Y19: 1 | Z19: 3 | AA19: 0 | AB19: 0 | AC19: 4 | AD19: 3 | AE19: 4 | AF19: 8 | AG19: 722 | AH19: 5 | AI19: 16 | AJ19: 64 | AK19: 56 | AL19: 70 | AM19: 69 | AN19: 70 | AO19: 44 | AP19: 26 | AQ19: 302
A20: Taipei City | C20: 女 Female | D20: 819 | E20: 752 | F20: 12 | G20: 5 | H20: 23 | I20: 0 | J20: 27 | K20: 819 | L20: 17 | M20: 40 | N20: 181 | O20: 174 | P20: 135 | Q20: 149 | R20: 79 | S20: 25 | T20: 11 | U20: 8 | V20: 819 | W20: 723 | X20: 14 | Y20: 1 | Z20: 30 | AA20: 0 | AB20: 1 | AC20: 4 | AD20: 7 | AE20: 12 | AF20: 27 | AG20: 53 | AH20: 0 | AI20: 6 | AJ20: 20 | AK20: 4 | AL20: 3 | AM20: 4 | AN20: 2 | AO20: 4 | AP20: 0 | AQ20: 10
C21: 其他 Other | D21: 0 | E21: 0 | F21: 0 | G21: 0 | H21: 0 | I21: 0 | J21: 0 | K21: 0 | L21: 0 | M21: 0 | N21: 0 | O21: 0 | P21: 0 | Q21: 0 | R21: 0 | S21: 0 | T21: 0 | U21: 0 | V21: 0 | W21: 0 | X21: 0 | Y21: 0 | Z21: 0 | AA21: 0 | AB21: 0 | AC21: 0 | AD21: 0 | AE21: 0 | AF21: 0 | AG21: 0 | AH21: 0 | AI21: 0 | AJ21: 0 | AK21: 0 | AL21: 0 | AM21: 0 | AN21: 0 | AO21: 0 | AP21: 0 | AQ21: 0
C22: 不詳Unknown | D22: 4 | E22: 1 | F22: 0 | G22: 0 | H22: 0 | I22: 0 | J22: 3 | K22: 4 | L22: 0 | M22: 0 | N22: 0 | O22: 1 | P22: 1 | Q22: 0 | R22: 0 | S22: 0 | T22: 0 | U22: 2 | V22: 4 | W22: 0 | X22: 0 | Y22: 0 | Z22: 0 | AA22: 0 | AB22: 0 | AC22: 0 | AD22: 0 | AE22: 0 | AF22: 4 | AG22: 24 | AH22: 0 | AI22: 0 | AJ22: 0 | AK22: 1 | AL22: 0 | AM22: 0 | AN22: 1 | AO22: 0 | AP22: 0 | AQ22: 22
A23: 桃園市 | C23: 計 Total | D23: 1148 | E23: 975 | F23: 136 | G23: 6 | H23: 28 | I23: 0 | J23: 3 | K23: 1148 | L23: 17 | M23: 77 | N23: 469 | O23: 172 | P23: 131 | Q23: 153 | R23: 94 | S23: 25 | T23: 9 | U23: 1 | V23: 1148 | W23: 1039 | X23: 43 | Y23: 1 | Z23: 25 | AA23: 0 | AB23: 5 | AC23: 3 | AD23: 10 | AE23: 12 | AF23: 10 | AG23: 1134 | AH23: 1 | AI23: 21 | AJ23: 200 | AK23: 139 | AL23: 93 | AM23: 109 | AN23: 108 | AO23: 70 | AP23: 31 | AQ23: 362
C24: 男 Male | D24: 170 | E24: 145 | F24: 23 | G24: 0 | H24: 2 | I24: 0 | J24: 0 | K24: 170 | L24: 3 | M24: 19 | N24: 89 | O24: 23 | P24: 12 | Q24: 13 | R24: 8 | S24: 1 | T24: 1 | U24: 1 | V24: 170 | W24: 149 | X24: 6 | Y24: 0 | Z24: 3 | AA24: 0 | AB24: 1 | AC24: 0 | AD24: 2 | AE24: 7 | AF24: 2 | AG24: 1005 | AH24: 1 | AI24: 15 | AJ24: 148 | AK24: 135 | AL24: 91 | AM24: 106 | AN24: 103 | AO24: 70 | AP24: 30 | AQ24: 306
A25: Taoyuan City | C25: 女 Female | D25: 977 | E25: 829 | F25: 113 | G25: 6 | H25: 26 | I25: 0 | J25: 3 | K25: 977 | L25: 14 | M25: 58 | N25: 379 | O25: 149 | P25: 119 | Q25: 140 | R25: 86 | S25: 24 | T25: 8 | U25: 0 | V25: 977 | W25: 889 | X25: 37 | Y25: 1 | Z25: 22 | AA25: 0 | AB25: 4 | AC25: 3 | AD25: 8 | AE25: 5 | AF25: 8 | AG25: 88 | AH25: 0 | AI25: 6 | AJ25: 52 | AK25: 4 | AL25: 2 | AM25: 3 | AN25: 5 | AO25: 0 | AP25: 1 | AQ25: 15
C26: 其他 Other | D26: 0 | E26: 0 | F26: 0 | G26: 0 | H26: 0 | I26: 0 | J26: 0 | K26: 0 | L26: 0 | M26: 0 | N26: 0 | O26: 0 | P26: 0 | Q26: 0 | R26: 0 | S26: 0 | T26: 0 | U26: 0 | V26: 0 | W26: 0 | X26: 0 | Y26: 0 | Z26: 0 | AA26: 0 | AB26: 0 | AC26: 0 | AD26: 0 | AE26: 0 | AF26: 0 | AG26: 0 | AH26: 0 | AI26: 0 | AJ26: 0 | AK26: 0 | AL26: 0 | AM26: 0 | AN26: 0 | AO26: 0 | AP26: 0 | AQ26: 0
C27: 不詳Unknown | D27: 1 | E27: 1 | F27: 0 | G27: 0 | H27: 0 | I27: 0 | J27: 0 | K27: 1 | L27: 0 | M27: 0 | N27: 1 | O27: 0 | P27: 0 | Q27: 0 | R27: 0 | S27: 0 | T27: 0 | U27: 0 | V27: 1 | W27: 1 | X27: 0 | Y27: 0 | Z27: 0 | AA27: 0 | AB27: 0 | AC27: 0 | AD27: 0 | AE27: 0 | AF27: 0 | AG27: 41 | AH27: 0 | AI27: 0 | AJ27: 0 | AK27: 0 | AL27: 0 | AM27: 0 | AN27: 0 | AO27: 0 | AP27: 0 | AQ27: 41
A28: 臺中市 | C28: 計 Total | D28: 1305 | E28: 1180 | F28: 53 | G28: 5 | H28: 18 | I28: 0 | J28: 49 | K28: 1305 | L28: 32 | M28: 72 | N28: 435 | O28: 238 | P28: 160 | Q28: 193 | R28: 117 | S28: 45 | T28: 7 | U28: 6 | V28: 1305 | W28: 1155 | X28: 44 | Y28: 1 | Z28: 54 | AA28: 2 | AB28: 2 | AC28: 8 | AD28: 14 | AE28: 14 | AF28: 11 | AG28: 1207 | AH28: 3 | AI28: 24 | AJ28: 216 | AK28: 137 | AL28: 95 | AM28: 138 | AN28: 121 | AO28: 74 | AP28: 37 | AQ28: 362
C29: 男 Male | D29: 192 | E29: 167 | F29: 11 | G29: 1 | H29: 1 | I29: 0 | J29: 12 | K29: 192 | L29: 6 | M29: 22 | N29: 102 | O29: 17 | P29: 19 | Q29: 19 | R29: 5 | S29: 2 | T29: 0 | U29: 0 | V29: 192 | W29: 176 | X29: 6 | Y29: 0 | Z29: 3 | AA29: 0 | AB29: 0 | AC29: 1 | AD29: 3 | AE29: 3 | AF29: 0 | AG29: 1065 | AH29: 2 | AI29: 19 | AJ29: 165 | AK29: 132 | AL29: 92 | AM29: 133 | AN29: 117 | AO29: 72 | AP29: 35 | AQ29: 298
A30: Taichung City | C30: 女 Female | D30: 1105 | E30: 1011 | F30: 41 | G30: 4 | H30: 17 | I30: 0 | J30: 32 | K30: 1105 | L30: 26 | M30: 50 | N30: 327 | O30: 221 | P30: 141 | Q30: 174 | R30: 112 | S30: 43 | T30: 7 | U30: 4 | V30: 1105 | W30: 974 | X30: 38 | Y30: 1 | Z30: 51 | AA30: 2 | AB30: 2 | AC30: 7 | AD30: 11 | AE30: 10 | AF30: 9 | AG30: 83 | AH30: 1 | AI30: 5 | AJ30: 46 | AK30: 5 | AL30: 2 | AM30: 4 | AN30: 4 | AO30: 2 | AP30: 2 | AQ30: 12
C31: 其他 Other | D31: 0 | E31: 0 | F31: 0 | G31: 0 | H31: 0 | I31: 0 | J31: 0 | K31: 0 | L31: 0 | M31: 0 | N31: 0 | O31: 0 | P31: 0 | Q31: 0 | R31: 0 | S31: 0 | T31: 0 | U31: 0 | V31: 0 | W31: 0 | X31: 0 | Y31: 0 | Z31: 0 | AA31: 0 | AB31: 0 | AC31: 0 | AD31: 0 | AE31: 0 | AF31: 0 | AG31: 0 | AH31: 0 | AI31: 0 | AJ31: 0 | AK31: 0 | AL31: 0 | AM31: 0 | AN31: 0 | AO31: 0 | AP31: 0 | AQ31: 0
C32: 不詳Unknown | D32: 8 | E32: 2 | F32: 1 | G32: 0 | H32: 0 | I32: 0 | J32: 5 | K32: 8 | L32: 0 | M32: 0 | N32: 6 | O32: 0 | P32: 0 | Q32: 0 | R32: 0 | S32: 0 | T32: 0 | U32: 2 | V32: 8 | W32: 5 | X32: 0 | Y32: 0 | Z32: 0 | AA32: 0 | AB32: 0 | AC32: 0 | AD32: 0 | AE32: 1 | AF32: 2 | AG32: 59 | AH32: 0 | AI32: 0 | AJ32: 5 | AK32: 0 | AL32: 1 | AM32: 1 | AN32: 0 | AO32: 0 | AP32: 0 | AQ32: 52
A33: 臺南市 | C33: 計 Total | D33: 736 | E33: 703 | F33: 18 | G33: 2 | H33: 12 | I33: 0 | J33: 1 | K33: 736 | L33: 22 | M33: 72 | N33: 245 | O33: 100 | P33: 89 | Q33: 94 | R33: 62 | S33: 40 | T33: 10 | U33: 2 | V33: 736 | W33: 659 | X33: 21 | Y33: 2 | Z33: 26 | AA33: 0 | AB33: 0 | AC33: 7 | AD33: 5 | AE33: 14 | AF33: 2 | AG33: 707 | AH33: 4 | AI33: 20 | AJ33: 129 | AK33: 90 | AL33: 59 | AM33: 83 | AN33: 92 | AO33: 68 | AP33: 31 | AQ33: 131
C34: 男 Male | D34: 121 | E34: 117 | F34: 2 | G34: 0 | H34: 2 | I34: 0 | J34: 0 | K34: 121 | L34: 5 | M34: 23 | N34: 55 | O34: 8 | P34: 10 | Q34: 13 | R34: 5 | S34: 2 | T34: 0 | U34: 0 | V34: 121 | W34: 108 | X34: 3 | Y34: 0 | Z34: 5 | AA34: 0 | AB34: 0 | AC34: 1 | AD34: 1 | AE34: 3 | AF34: 0 | AG34: 641 | AH34: 4 | AI34: 13 | AJ34: 100 | AK34: 87 | AL34: 53 | AM34: 79 | AN34: 90 | AO34: 66 | AP34: 30 | AQ34: 119
A35: Tainan City | C35: 女 Female | D35: 615 | E35: 586 | F35: 16 | G35: 2 | H35: 10 | I35: 0 | J35: 1 | K35: 615 | L35: 17 | M35: 49 | N35: 190 | O35: 92 | P35: 79 | Q35: 81 | R35: 57 | S35: 38 | T35: 10 | U35: 2 | V35: 615 | W35: 551 | X35: 18 | Y35: 2 | Z35: 21 | AA35: 0 | AB35: 0 | AC35: 6 | AD35: 4 | AE35: 11 | AF35: 2 | AG35: 56 | AH35: 0 | AI35: 7 | AJ35: 29 | AK35: 3 | AL35: 6 | AM35: 4 | AN35: 2 | AO35: 1 | AP35: 1 | AQ35: 3
C36: 其他 Other | D36: 0 | E36: 0 | F36: 0 | G36: 0 | H36: 0 | I36: 0 | J36: 0 | K36: 0 | L36: 0 | M36: 0 | N36: 0 | O36: 0 | P36: 0 | Q36: 0 | R36: 0 | S36: 0 | T36: 0 | U36: 0 | V36: 0 | W36: 0 | X36: 0 | Y36: 0 | Z36: 0 | AA36: 0 | AB36: 0 | AC36: 0 | AD36: 0 | AE36: 0 | AF36: 0 | AG36: 0 | AH36: 0 | AI36: 0 | AJ36: 0 | AK36: 0 | AL36: 0 | AM36: 0 | AN36: 0 | AO36: 0 | AP36: 0 | AQ36: 0
C37: 不詳Unknown | D37: 0 | E37: 0 | F37: 0 | G37: 0 | H37: 0 | I37: 0 | J37: 0 | K37: 0 | L37: 0 | M37: 0 | N37: 0 | O37: 0 | P37: 0 | Q37: 0 | R37: 0 | S37: 0 | T37: 0 | U37: 0 | V37: 0 | W37: 0 | X37: 0 | Y37: 0 | Z37: 0 | AA37: 0 | AB37: 0 | AC37: 0 | AD37: 0 | AE37: 0 | AF37: 0 | AG37: 10 | AH37: 0 | AI37: 0 | AJ37: 0 | AK37: 0 | AL37: 0 | AM37: 0 | AN37: 0 | AO37: 1 | AP37: 0 | AQ37: 9
A38: 高雄市 | C38: 計 Total | D38: 991 | E38: 910 | F38: 57 | G38: 4 | H38: 19 | I38: 0 | J38: 1 | K38: 991 | L38: 20 | M38: 70 | N38: 390 | O38: 157 | P38: 104 | Q38: 128 | R38: 72 | S38: 40 | T38: 9 | U38: 1 | V38: 991 | W38: 869 | X38: 38 | Y38: 2 | Z38: 35 | AA38: 3 | AB38: 3 | AC38: 7 | AD38: 11 | AE38: 17 | AF38: 6 | AG38: 895 | AH38: 2 | AI38: 14 | AJ38: 184 | AK38: 99 | AL38: 53 | AM38: 105 | AN38: 93 | AO38: 87 | AP38: 35 | AQ38: 223
C39: 男 Male | D39: 168 | E39: 160 | F39: 8 | G39: 0 | H39: 0 | I39: 0 | J39: 0 | K39: 168 | L39: 6 | M39: 18 | N39: 97 | O39: 16 | P39: 13 | Q39: 13 | R39: 2 | S39: 3 | T39: 0 | U39: 0 | V39: 168 | W39: 147 | X39: 7 | Y39: 1 | Z39: 2 | AA39: 1 | AB39: 0 | AC39: 2 | AD39: 3 | AE39: 5 | AF39: 0 | AG39: 770 | AH39: 2 | AI39: 12 | AJ39: 118 | AK39: 96 | AL39: 53 | AM39: 101 | AN39: 91 | AO39: 83 | AP39: 32 | AQ39: 182
A40: Kaohsiung City | C40: 女 Female | D40: 823 | E40: 750 | F40: 49 | G40: 4 | H40: 19 | I40: 0 | J40: 1 | K40: 823 | L40: 14 | M40: 52 | N40: 293 | O40: 141 | P40: 91 | Q40: 115 | R40: 70 | S40: 37 | T40: 9 | U40: 1 | V40: 823 | W40: 722 | X40: 31 | Y40: 1 | Z40: 33 | AA40: 2 | AB40: 3 | AC40: 5 | AD40: 8 | AE40: 12 | AF40: 6 | AG40: 87 | AH40: 0 | AI40: 2 | AJ40: 66 | AK40: 3 | AL40: 0 | AM40: 4 | AN40: 2 | AO40: 4 | AP40: 2 | AQ40: 4
...

Sheet July-Dec., 2025
A1: 性侵害事件通報被害及嫌疑人概況 Overview of Victim and Offender Status in Reporting Sexual Assault Cases
A2: 114年下半年 July-Dec., 2025
A3: 單位：人 unit:Person
A4: 區域別 | C4: 性別 | D4: 性侵害被害人統計 Statistics of Sexual Assault Victims | AG4: 性侵害嫌疑人年齡統計 Statistics of Age of Sexual Assault Offenders
D5: 國籍、身分別 By Nationality and Identity | K5: 年齡別 By Age | V5: 身心障礙別 By Disability | AG5: 年齡別 By Age
D6: 合計 | E6: 本國籍 非原住民 | F6: 本國籍 原住民 | G6: 大陸及 港澳籍 | H6: 外國籍 | I6: 無國籍 | J6: 資料 不明 | K6: 合計 | L6: 0-未滿6歲 | M6: 6-未滿12歲 | N6: 12-未滿18歲 | O6: 18-未滿24歲 | P6: 24-未滿30歲 | Q6: 30-未滿40歲 | R6: 40-未滿50歲 | S6: 50-未滿65歲 | T6: 65歲 以上 | U6: 不詳 | V6: 合計 | W6: 非身心 障礙 | X6: 智障 | Y6: 視障 | Z6: 精神 病患 | AA6: 聲(語)障 | AB6: 聽障 | AC6: 肢障 | AD6: 多重 障礙 | AE6: 其他 障礙 | AF6: 不詳 | AG6: 合計 | AH6: 0-未滿6歲 | AI6: 6-未滿12歲 | AJ6: 12-未滿18歲 | AK6: 18-未滿24歲 | AL6: 24-未滿30歲 | AM6: 30-未滿40歲 | AN6: 40-未滿50歲 | AO6: 50-未滿65歲 | AP6: 65歲 以上 | AQ6: 不詳
A7: Locality | C7: Gender | D7: Total | E7: Non-Indigenous Native | F7: Indigenous Native | G7: Mainland China and Hong Kong and Macau | H7: Foreign | I7: Stateless | J7: Unknown Information | K7: Total | L7: Under 6 Years | M7: 6-Under 12 Years | N7: 12-Under 18 Years | O7: 18-Under 24 Years | P7: 24-Under 30 Years | Q7: 30-Under 40 Years | R7: 40-Under 50 Years | S7: 50-Under 65 Years | T7: Above 65 Years | U7: Unknown | V7: Total | W7: Not Disability | X7: Intellectually Disabled | Y7: Vision | Z7: Mentally Illed | AA7: Voice | AB7: Hearing | AC7: Physically Impaired | AD7: Multiple | AE7: Other | AF7: Unknown | AG7: Total | AH7: Under 6 Years | AI7: 6-Under 12 Years | AJ7: 12-Under 18 Years | AK7: 18-Under 2 Years | AL7: 24-Under 30 Years | AM7: 30-Under 40 Years | AN7: 40-Under 50 Years | AO7: 50-Under 65 Years | AP7: Above 65 Years | AQ7: Unknown
A8: 總計 | C8: 計 Total | D8: 4505 | E8: 3932 | F8: 352 | G8: 23 | H8: 92 | I8: 0 | J8: 106 | K8: 4505 | L8: 108 | M8: 347 | N8: 1594 | O8: 737 | P8: 531 | Q8: 612 | R8: 354 | S8: 147 | T8: 57 | U8: 18 | V8: 4505 | W8: 3930 | X8: 168 | Y8: 7 | Z8: 166 | AA8: 4 | AB8: 11 | AC8: 29 | AD8: 61 | AE8: 74 | AF8: 55 | AG8: 4197 | AH8: 16 | AI8: 89 | AJ8: 708 | AK8: 475 | AL8: 332 | AM8: 445 | AN8: 466 | AO8: 278 | AP8: 162 | AQ8: 1226
C9: 男 Male | D9: 700 | E9: 600 | F9: 71 | G9: 4 | H9: 8 | I9: 0 | J9: 17 | K9: 700 | L9: 16 | M9: 102 | N9: 326 | O9: 79 | P9: 61 | Q9: 66 | R9: 29 | S9: 15 | T9: 3 | U9: 3 | V9: 700 | W9: 602 | X9: 24 | Y9: 1 | Z9: 22 | AA9: 1 | AB9: 0 | AC9: 3 | AD9: 14 | AE9: 23 | AF9: 10 | AG9: 3687 | AH9: 14 | AI9: 68 | AJ9: 496 | AK9: 457 | AL9: 316 | AM9: 424 | AN9: 446 | AO9: 264 | AP9: 155 | AQ9: 1047
A10: Total | C10: 女 Female | D10: 3796 | E10: 3326 | F10: 280 | G10: 19 | H10: 84 | I10: 0 | J10: 87 | K10: 3796 | L10: 92 | M10: 245 | N10: 1262 | O10: 656 | P10: 470 | Q10: 546 | R10: 325 | S10: 132 | T10: 54 | U10: 14 | V10: 3796 | W10: 3321 | X10: 144 | Y10: 6 | Z10: 144 | AA10: 3 | AB10: 11 | AC10: 26 | AD10: 47 | AE10: 51 | AF10: 43 | AG10: 370 | AH10: 2 | AI10: 21 | AJ10: 207 | AK10: 18 | AL10: 15 | AM10: 20 | AN10: 19 | AO10: 13 | AP10: 6 | AQ10: 49
C11: 其他 Other | D11: 0 | E11: 0 | F11: 0 | G11: 0 | H11: 0 | I11: 0 | J11: 0 | K11: 0 | L11: 0 | M11: 0 | N11: 0 | O11: 0 | P11: 0 | Q11: 0 | R11: 0 | S11: 0 | T11: 0 | U11: 0 | V11: 0 | W11: 0 | X11: 0 | Y11: 0 | Z11: 0 | AA11: 0 | AB11: 0 | AC11: 0 | AD11: 0 | AE11: 0 | AF11: 0 | AG11: 0 | AH11: 0 | AI11: 0 | AJ11: 0 | AK11: 0 | AL11: 0 | AM11: 0 | AN11: 0 | AO11: 0 | AP11: 0 | AQ11: 0
C12: 不詳Unknown | D12: 9 | E12: 6 | F12: 1 | G12: 0 | H12: 0 | I12: 0 | J12: 2 | K12: 9 | L12: 0 | M12: 0 | N12: 6 | O12: 2 | P12: 0 | Q12: 0 | R12: 0 | S12: 0 | T12: 0 | U12: 1 | V12: 9 | W12: 7 | X12: 0 | Y12: 0 | Z12: 0 | AA12: 0 | AB12: 0 | AC12: 0 | AD12: 0 | AE12: 0 | AF12: 2 | AG12: 140 | AH12: 0 | AI12: 0 | AJ12: 5 | AK12: 0 | AL12: 1 | AM12: 1 | AN12: 1 | AO12: 1 | AP12: 1 | AQ12: 130
A13: 新北市 | C13: 計 Total | D13: 791 | E13: 702 | F13: 32 | G13: 4 | H13: 14 | I13: 0 | J13: 39 | K13: 791 | L13: 16 | M13: 58 | N13: 276 | O13: 132 | P13: 116 | Q13: 114 | R13: 46 | S13: 17 | T13: 9 | U13: 7 | V13: 791 | W13: 699 | X13: 26 | Y13: 0 | Z13: 25 | AA13: 0 | AB13: 1 | AC13: 5 | AD13: 9 | AE13: 12 | AF13: 14 | AG13: 736 | AH13: 2 | AI13: 13 | AJ13: 126 | AK13: 77 | AL13: 48 | AM13: 62 | AN13: 83 | AO13: 37 | AP13: 23 | AQ13: 265
C14: 男 Male | D14: 119 | E14: 108 | F14: 5 | G14: 2 | H14: 0 | I14: 0 | J14: 4 | K14: 119 | L14: 2 | M14: 19 | N14: 57 | O14: 13 | P14: 11 | Q14: 12 | R14: 3 | S14: 1 | T14: 0 | U14: 1 | V14: 119 | W14: 100 | X14: 5 | Y14: 0 | Z14: 6 | AA14: 0 | AB14: 0 | AC14: 0 | AD14: 2 | AE14: 4 | AF14: 2 | AG14: 629 | AH14: 1 | AI14: 9 | AJ14: 85 | AK14: 76 | AL14: 44 | AM14: 56 | AN14: 75 | AO14: 32 | AP14: 21 | AQ14: 230
A15: New Taipei City | C15: 女 Female | D15: 669 | E15: 591 | F15: 27 | G15: 2 | H15: 14 | I15: 0 | J15: 35 | K15: 669 | L15: 14 | M15: 39 | N15: 216 | O15: 119 | P15: 105 | Q15: 102 | R15: 43 | S15: 16 | T15: 9 | U15: 6 | V15: 669 | W15: 596 | X15: 21 | Y15: 0 | Z15: 19 | AA15: 0 | AB15: 1 | AC15: 5 | AD15: 7 | AE15: 8 | AF15: 12 | AG15: 84 | AH15: 1 | AI15: 4 | AJ15: 39 | AK15: 1 | AL15: 4 | AM15: 6 | AN15: 7 | AO15: 5 | AP15: 2 | AQ15: 15
C16: 其他 Other | D16: 0 | E16: 0 | F16: 0 | G16: 0 | H16: 0 | I16: 0 | J16: 0 | K16: 0 | L16: 0 | M16: 0 | N16: 0 | O16: 0 | P16: 0 | Q16: 0 | R16: 0 | S16: 0 | T16: 0 | U16: 0 | V16: 0 | W16: 0 | X16: 0 | Y16: 0 | Z16: 0 | AA16: 0 | AB16: 0 | AC16: 0 | AD16: 0 | AE16: 0 | AF16: 0 | AG16: 0 | AH16: 0 | AI16: 0 | AJ16: 0 | AK16: 0 | AL16: 0 | AM16: 0 | AN16: 0 | AO16: 0 | AP16: 0 | AQ16: 0
C17: 不詳Unknown | D17: 3 | E17: 3 | F17: 0 | G17: 0 | H17: 0 | I17: 0 | J17: 0 | K17: 3 | L17: 0 | M17: 0 | N17: 3 | O17: 0 | P17: 0 | Q17: 0 | R17: 0 | S17: 0 | T17: 0 | U17: 0 | V17: 3 | W17: 3 | X17: 0 | Y17: 0 | Z17: 0 | AA17: 0 | AB17: 0 | AC17: 0 | AD17: 0 | AE17: 0 | AF17: 0 | AG17: 23 | AH17: 0 | AI17: 0 | AJ17: 2 | AK17: 0 | AL17: 0 | AM17: 0 | AN17: 1 | AO17: 0 | AP17: 0 | AQ17: 20
A18: 臺北市 | C18: 計 Total | D18: 453 | E18: 410 | F18: 6 | G18: 6 | H18: 15 | I18: 0 | J18: 16 | K18: 453 | L18: 8 | M18: 24 | N18: 97 | O18: 94 | P18: 77 | Q18: 84 | R18: 43 | S18: 11 | T18: 11 | U18: 4 | V18: 453 | W18: 393 | X18: 9 | Y18: 0 | Z18: 16 | AA18: 0 | AB18: 1 | AC18: 5 | AD18: 6 | AE18: 7 | AF18: 16 | AG18: 400 | AH18: 4 | AI18: 4 | AJ18: 32 | AK18: 22 | AL18: 42 | AM18: 34 | AN18: 42 | AO18: 22 | AP18: 19 | AQ18: 179
C19: 男 Male | D19: 64 | E19: 52 | F19: 1 | G19: 1 | H19: 5 | I19: 0 | J19: 5 | K19: 64 | L19: 1 | M19: 4 | N19: 18 | O19: 15 | P19: 10 | Q19: 8 | R19: 4 | S19: 2 | T19: 1 | U19: 1 | V19: 64 | W19: 51 | X19: 0 | Y19: 0 | Z19: 2 | AA19: 0 | AB19: 0 | AC19: 2 | AD19: 2 | AE19: 2 | AF19: 5 | AG19: 366 | AH19: 4 | AI19: 3 | AJ19: 25 | AK19: 21 | AL19: 41 | AM19: 32 | AN19: 41 | AO19: 19 | AP19: 19 | AQ19: 161
A20: Taipei City | C20: 女 Female | D20: 388 | E20: 358 | F20: 5 | G20: 5 | H20: 10 | I20: 0 | J20: 10 | K20: 388 | L20: 7 | M20: 20 | N20: 79 | O20: 78 | P20: 67 | Q20: 76 | R20: 39 | S20: 9 | T20: 10 | U20: 3 | V20: 388 | W20: 342 | X20: 9 | Y20: 0 | Z20: 14 | AA20: 0 | AB20: 1 | AC20: 3 | AD20: 4 | AE20: 5 | AF20: 10 | AG20: 22 | AH20: 0 | AI20: 1 | AJ20: 7 | AK20: 1 | AL20: 1 | AM20: 2 | AN20: 1 | AO20: 3 | AP20: 0 | AQ20: 6
C21: 其他 Other | D21: 0 | E21: 0 | F21: 0 | G21: 0 | H21: 0 | I21: 0 | J21: 0 | K21: 0 | L21: 0 | M21: 0 | N21: 0 | O21: 0 | P21: 0 | Q21: 0 | R21: 0 | S21: 0 | T21: 0 | U21: 0 | V21: 0 | W21: 0 | X21: 0 | Y21: 0 | Z21: 0 | AA21: 0 | AB21: 0 | AC21: 0 | AD21: 0 | AE21: 0 | AF21: 0 | AG21: 0 | AH21: 0 | AI21: 0 | AJ21: 0 | AK21: 0 | AL21: 0 | AM21: 0 | AN21: 0 | AO21: 0 | AP21: 0 | AQ21: 0
C22: 不詳Unknown | D22: 1 | E22: 0 | F22: 0 | G22: 0 | H22: 0 | I22: 0 | J22: 1 | K22: 1 | L22: 0 | M22: 0 | N22: 0 | O22: 1 | P22: 0 | Q22: 0 | R22: 0 | S22: 0 | T22: 0 | U22: 0 | V22: 1 | W22: 0 | X22: 0 | Y22: 0 | Z22: 0 | AA22: 0 | AB22: 0 | AC22: 0 | AD22: 0 | AE22: 0 | AF22: 1 | AG22: 12 | AH22: 0 | AI22: 0 | AJ22: 0 | AK22: 0 | AL22: 0 | AM22: 0 | AN22: 0 | AO22: 0 | AP22: 0 | AQ22: 12
A23: 桃園市 | C23: 計 Total | D23: 591 | E23: 497 | F23: 77 | G23: 3 | H23: 13 | I23: 0 | J23: 1 | K23: 591 | L23: 8 | M23: 45 | N23: 226 | O23: 91 | P23: 61 | Q23: 88 | R23: 49 | S23: 16 | T23: 6 | U23: 1 | V23: 591 | W23: 527 | X23: 22 | Y23: 1 | Z23: 14 | AA23: 0 | AB23: 2 | AC23: 2 | AD23: 8 | AE23: 9 | AF23: 6 | AG23: 586 | AH23: 0 | AI23: 11 | AJ23: 95 | AK23: 74 | AL23: 47 | AM23: 53 | AN23: 60 | AO23: 35 | AP23: 19 | AQ23: 192
C24: 男 Male | D24: 82 | E24: 69 | F24: 12 | G24: 0 | H24: 1 | I24: 0 | J24: 0 | K24: 82 | L24: 0 | M24: 12 | N24: 36 | O24: 11 | P24: 7 | Q24: 7 | R24: 7 | S24: 0 | T24: 1 | U24: 1 | V24: 82 | W24: 68 | X24: 3 | Y24: 0 | Z24: 2 | AA24: 0 | AB24: 0 | AC24: 0 | AD24: 2 | AE24: 5 | AF24: 2 | AG24: 511 | AH24: 0 | AI24: 6 | AJ24: 69 | AK24: 71 | AL24: 45 | AM24: 52 | AN24: 56 | AO24: 35 | AP24: 19 | AQ24: 158
A25: Taoyuan City | C25: 女 Female | D25: 509 | E25: 428 | F25: 65 | G25: 3 | H25: 12 | I25: 0 | J25: 1 | K25: 509 | L25: 8 | M25: 33 | N25: 190 | O25: 80 | P25: 54 | Q25: 81 | R25: 42 | S25: 16 | T25: 5 | U25: 0 | V25: 509 | W25: 459 | X25: 19 | Y25: 1 | Z25: 12 | AA25: 0 | AB25: 2 | AC25: 2 | AD25: 6 | AE25: 4 | AF25: 4 | AG25: 47 | AH25: 0 | AI25: 5 | AJ25: 26 | AK25: 3 | AL25: 2 | AM25: 1 | AN25: 4 | AO25: 0 | AP25: 0 | AQ25: 6
C26: 其他 Other | D26: 0 | E26: 0 | F26: 0 | G26: 0 | H26: 0 | I26: 0 | J26: 0 | K26: 0 | L26: 0 | M26: 0 | N26: 0 | O26: 0 | P26: 0 | Q26: 0 | R26: 0 | S26: 0 | T26: 0 | U26: 0 | V26: 0 | W26: 0 | X26: 0 | Y26: 0 | Z26: 0 | AA26: 0 | AB26: 0 | AC26: 0 | AD26: 0 | AE26: 0 | AF26: 0 | AG26: 0 | AH26: 0 | AI26: 0 | AJ26: 0 | AK26: 0 | AL26: 0 | AM26: 0 | AN26: 0 | AO26: 0 | AP26: 0 | AQ26: 0
C27: 不詳Unknown | D27: 0 | E27: 0 | F27: 0 | G27: 0 | H27: 0 | I27: 0 | J27: 0 | K27: 0 | L27: 0 | M27: 0 | N27: 0 | O27: 0 | P27: 0 | Q27: 0 | R27: 0 | S27: 0 | T27: 0 | U27: 0 | V27: 0 | W27: 0 | X27: 0 | Y27: 0 | Z27: 0 | AA27: 0 | AB27: 0 | AC27: 0 | AD27: 0 | AE27: 0 | AF27: 0 | AG27: 28 | AH27: 0 | AI27: 0 | AJ27: 0 | AK27: 0 | AL27: 0 | AM27: 0 | AN27: 0 | AO27: 0 | AP27: 0 | AQ27: 28
A28: 臺中市 | C28: 計 Total | D28: 620 | E28: 569 | F28: 15 | G28: 3 | H28: 8 | I28: 0 | J28: 25 | K28: 620 | L28: 17 | M28: 39 | N28: 191 | O28: 119 | P28: 67 | Q28: 91 | R28: 61 | S28: 25 | T28: 6 | U28: 4 | V28: 620 | W28: 539 | X28: 23 | Y28: 1 | Z28: 27 | AA28: 2 | AB28: 1 | AC28: 3 | AD28: 10 | AE28: 10 | AF28: 4 | AG28: 585 | AH28: 3 | AI28: 16 | AJ28: 92 | AK28: 73 | AL28: 47 | AM28: 75 | AN28: 63 | AO28: 28 | AP28: 19 | AQ28: 169
C29: 男 Male | D29: 85 | E29: 73 | F29: 4 | G29: 1 | H29: 1 | I29: 0 | J29: 6 | K29: 85 | L29: 3 | M29: 11 | N29: 40 | O29: 8 | P29: 10 | Q29: 10 | R29: 1 | S29: 2 | T29: 0 | U29: 0 | V29: 85 | W29: 76 | X29: 3 | Y29: 0 | Z29: 1 | AA29: 0 | AB29: 0 | AC29: 0 | AD29: 2 | AE29: 3 | AF29: 0 | AG29: 520 | AH29: 2 | AI29: 13 | AJ29: 73 | AK29: 69 | AL29: 46 | AM29: 72 | AN29: 60 | AO29: 28 | AP29: 18 | AQ29: 139
A30: Taichung City | C30: 女 Female | D30: 534 | E30: 496 | F30: 11 | G30: 2 | H30: 7 | I30: 0 | J30: 18 | K30: 534 | L30: 14 | M30: 28 | N30: 151 | O30: 111 | P30: 57 | Q30: 81 | R30: 60 | S30: 23 | T30: 6 | U30: 3 | V30: 534 | W30: 463 | X30: 20 | Y30: 1 | Z30: 26 | AA30: 2 | AB30: 1 | AC30: 3 | AD30: 8 | AE30: 7 | AF30: 3 | AG30: 35 | AH30: 1 | AI30: 3 | AJ30: 17 | AK30: 4 | AL30: 0 | AM30: 2 | AN30: 3 | AO30: 0 | AP30: 1 | AQ30: 4
C31: 其他 Other | D31: 0 | E31: 0 | F31: 0 | G31: 0 | H31: 0 | I31: 0 | J31: 0 | K31: 0 | L31: 0 | M31: 0 | N31: 0 | O31: 0 | P31: 0 | Q31: 0 | R31: 0 | S31: 0 | T31: 0 | U31: 0 | V31: 0 | W31: 0 | X31: 0 | Y31: 0 | Z31: 0 | AA31: 0 | AB31: 0 | AC31: 0 | AD31: 0 | AE31: 0 | AF31: 0 | AG31: 0 | AH31: 0 | AI31: 0 | AJ31: 0 | AK31: 0 | AL31: 0 | AM31: 0 | AN31: 0 | AO31: 0 | AP31: 0 | AQ31: 0
C32: 不詳Unknown | D32: 1 | E32: 0 | F32: 0 | G32: 0 | H32: 0 | I32: 0 | J32: 1 | K32: 1 | L32: 0 | M32: 0 | N32: 0 | O32: 0 | P32: 0 | Q32: 0 | R32: 0 | S32: 0 | T32: 0 | U32: 1 | V32: 1 | W32: 0 | X32: 0 | Y32: 0 | Z32: 0 | AA32: 0 | AB32: 0 | AC32: 0 | AD32: 0 | AE32: 0 | AF32: 1 | AG32: 30 | AH32: 0 | AI32: 0 | AJ32: 2 | AK32: 0 | AL32: 1 | AM32: 1 | AN32: 0 | AO32: 0 | AP32: 0 | AQ32: 26
A33: 臺南市 | C33: 計 Total | D33: 360 | E33: 341 | F33: 9 | G33: 1 | H33: 9 | I33: 0 | J33: 0 | K33: 360 | L33: 10 | M33: 45 | N33: 106 | O33: 53 | P33: 41 | Q33: 49 | R33: 31 | S33: 20 | T33: 5 | U33: 0 | V33: 360 | W33: 320 | X33: 10 | Y33: 1 | Z33: 16 | AA33: 0 | AB33: 0 | AC33: 3 | AD33: 3 | AE33: 7 | AF33: 0 | AG33: 348 | AH33: 3 | AI33: 9 | AJ33: 57 | AK33: 36 | AL33: 27 | AM33: 42 | AN33: 53 | AO33: 34 | AP33: 14 | AQ33: 73
C34: 男 Male | D34: 51 | E34: 50 | F34: 0 | G34: 0 | H34: 1 | I34: 0 | J34: 0 | K34: 51 | L34: 1 | M34: 12 | N34: 19 | O34: 3 | P34: 6 | Q34: 6 | R34: 3 | S34: 1 | T34: 0 | U34: 0 | V34: 51 | W34: 45 | X34: 1 | Y34: 0 | Z34: 4 | AA34: 0 | AB34: 0 | AC34: 0 | AD34: 0 | AE34: 1 | AF34: 0 | AG34: 322 | AH34: 3 | AI34: 6 | AJ34: 47 | AK34: 34 | AL34: 25 | AM34: 40 | AN34: 52 | AO34: 33 | AP34: 14 | AQ34: 68
A35: Tainan City | C35: 女 Female | D35: 309 | E35: 291 | F35: 9 | G35: 1 | H35: 8 | I35: 0 | J35: 0 | K35: 309 | L35: 9 | M35: 33 | N35: 87 | O35: 50 | P35: 35 | Q35: 43 | R35: 28 | S35: 19 | T35: 5 | U35: 0 | V35: 309 | W35: 275 | X35: 9 | Y35: 1 | Z35: 12 | AA35: 0 | AB35: 0 | AC35: 3 | AD35: 3 | AE35: 6 | AF35: 0 | AG35: 22 | AH35: 0 | AI35: 3 | AJ35: 10 | AK35: 2 | AL35: 2 | AM35: 2 | AN35: 1 | AO35: 0 | AP35: 0 | AQ35: 2
C36: 其他 Other | D36: 0 | E36: 0 | F36: 0 | G36: 0 | H36: 0 | I36: 0 | J36: 0 | K36: 0 | L36: 0 | M36: 0 | N36: 0 | O36: 0 | P36: 0 | Q36: 0 | R36: 0 | S36: 0 | T36: 0 | U36: 0 | V36: 0 | W36: 0 | X36: 0 | Y36: 0 | Z36: 0 | AA36: 0 | AB36: 0 | AC36: 0 | AD36: 0 | AE36: 0 | AF36: 0 | AG36: 0 | AH36: 0 | AI36: 0 | AJ36: 0 | AK36: 0 | AL36: 0 | AM36: 0 | AN36: 0 | AO36: 0 | AP36: 0 | AQ36: 0
C37: 不詳Unknown | D37: 0 | E37: 0 | F37: 0 | G37: 0 | H37: 0 | I37: 0 | J37: 0 | K37: 0 | L37: 0 | M37: 0 | N37: 0 | O37: 0 | P37: 0 | Q37: 0 | R37: 0 | S37: 0 | T37: 0 | U37: 0 | V37: 0 | W37: 0 | X37: 0 | Y37: 0 | Z37: 0 | AA37: 0 | AB37: 0 | AC37: 0 | AD37: 0 | AE37: 0 | AF37: 0 | AG37: 4 | AH37: 0 | AI37: 0 | AJ37: 0 | AK37: 0 | AL37: 0 | AM37: 0 | AN37: 0 | AO37: 1 | AP37: 0 | AQ37: 3
A38: 高雄市 | C38: 計 Total | D38: 460 | E38: 418 | F38: 29 | G38: 4 | H38: 9 | I38: 0 | J38: 0 | K38: 460 | L38: 10 | M38: 34 | N38: 153 | O38: 78 | P38: 52 | Q38: 62 | R38: 40 | S38: 22 | T38: 8 | U38: 1 | V38: 460 | W38: 392 | X38: 19 | Y38: 1 | Z38: 19 | AA38: 2 | AB38: 3 | AC38: 4 | AD38: 6 | AE38: 12 | AF38: 2 | AG38: 421 | AH38: 2 | AI38: 8 | AJ38: 66 | AK38: 47 | AL38: 27 | AM38: 50 | AN38: 47 | AO38: 41 | AP38: 22 | AQ38: 111
C39: 男 Male | D39: 75 | E39: 68 | F39: 7 | G39: 0 | H39: 0 | I39: 0 | J39: 0 | K39: 75 | L39: 2 | M39: 11 | N39: 38 | O39: 8 | P39: 5 | Q39: 7 | R39: 2 | S39: 2 | T39: 0 | U39: 0 | V39: 75 | W39: 65 | X39: 4 | Y39: 0 | Z39: 0 | AA39: 1 | AB39: 0 | AC39: 0 | AD39: 1 | AE39: 4 | AF39: 0 | AG39: 366 | AH39: 2 | AI39: 6 | AJ39: 43 | AK39: 45 | AL39: 27 | AM39: 49 | AN39: 46 | AO39: 40 | AP39: 19 | AQ39: 89
A40: Kaohsiung City | C40: 女 Female | D40: 385 | E40: 350 | F40: 22 | G40: 4 | H40: 9 | I40: 0 | J40: 0 | K40: 385 | L40: 8 | M40: 23 | N40: 115 | O40: 70 | P40: 47 | Q40: 55 | R40: 38 | S40: 20 | T40: 8 | U40: 1 | V40: 385 | W40: 327 | X40: 15 | Y40: 1 | Z40: 19 | AA40: 1 | AB40: 3 | AC40: 4 | AD40: 5 | AE40: 8 | AF40: 2 | AG40: 35 | AH40: 0 | AI40: 2 | AJ40: 23 | AK40: 2 | AL40: 0 | AM40: 1 | AN40: 1 | AO40: 1 | AP40: 2 | AQ40: 3
...

Sheet Jan.-June.,2025
A1: 性侵害事件通報被害及嫌疑人概況 Overview of Victim and Offender Status in Reporting Sexual Assault Cases
A2: 114年上半年 Jan.-June.,2025
A3: 單位：人 unit:Person
A4: 區域別 | C4: 性別 | D4: 性侵害被害人統計 Statistics of Sexual Assault Victims | AG4: 性侵害嫌疑人年齡統計 Statistics of Age of Sexual Assault Offenders
D5: 國籍、身分別 By Nationality and Identity | K5: 年齡別 By Age | V5: 身心障礙別 By Disability | AG5: 年齡別 By Age
D6: 合計 | E6: 本國籍 非原住民 | F6: 本國籍 原住民 | G6: 大陸及 港澳籍 | H6: 外國籍 | I6: 無國籍 | J6: 資料 不明 | K6: 合計 | L6: 0-未滿6歲 | M6: 6-未滿12歲 | N6: 12-未滿18歲 | O6: 18-未滿24歲 | P6: 24-未滿30歲 | Q6: 30-未滿40歲 | R6: 40-未滿50歲 | S6: 50-未滿65歲 | T6: 65歲 以上 | U6: 不詳 | V6: 合計 | W6: 非身心 障礙 | X6: 智障 | Y6: 視障 | Z6: 精神 病患 | AA6: 聲(語)障 | AB6: 聽障 | AC6: 肢障 | AD6: 多重 障礙 | AE6: 其他 障礙 | AF6: 不詳 | AG6: 合計 | AH6: 0-未滿6歲 | AI6: 6-未滿12歲 | AJ6: 12-未滿18歲 | AK6: 18-未滿24歲 | AL6: 24-未滿30歲 | AM6: 30-未滿40歲 | AN6: 40-未滿50歲 | AO6: 50-未滿65歲 | AP6: 65歲 以上 | AQ6: 不詳
A7: Locality | C7: Gender | D7: Total | E7: Non-Indigenous Native | F7: Indigenous Native | G7: Mainland China and Hong Kong and Macau | H7: Foreign | I7: Stateless | J7: Unknown Information | K7: Total | L7: Under 6 Years | M7: 6-Under 12 Years | N7: 12-Under 18 Years | O7: 18-Under 24 Years | P7: 24-Under 30 Years | Q7: 30-Under 40 Years | R7: 40-Under 50 Years | S7: 50-Under 65 Years | T7: Above 65 Years | U7: Unknown | V7: Total | W7: Not Disability | X7: Intellectually Disabled | Y7: Vision | Z7: Mentally Illed | AA7: Voice | AB7: Hearing | AC7: Physically Impaired | AD7: Multiple | AE7: Other | AF7: Unknown | AG7: Total | AH7: Under 6 Years | AI7: 6-Under 12 Years | AJ7: 12-Under 18 Years | AK7: 18-Under 2 Years | AL7: 24-Under 30 Years | AM7: 30-Under 40 Years | AN7: 40-Under 50 Years | AO7: 50-Under 65 Years | AP7: Above 65 Years | AQ7: Unknown
A8: 總計 | C8: 計 Total | D8: 5060 | E8: 4444 | F8: 409 | G8: 14 | H8: 83 | I8: 1 | J8: 109 | K8: 5060 | L8: 123 | M8: 405 | N8: 2135 | O8: 702 | P8: 549 | Q8: 594 | R8: 343 | S8: 144 | T8: 34 | U8: 31 | V8: 5060 | W8: 4544 | X8: 164 | Y8: 6 | Z8: 150 | AA8: 2 | AB8: 8 | AC8: 22 | AD8: 37 | AE8: 56 | AF8: 71 | AG8: 4571 | AH8: 9 | AI8: 108 | AJ8: 989 | AK8: 533 | AL8: 316 | AM8: 462 | AN8: 411 | AO8: 333 | AP8: 146 | AQ8: 1264
C9: 男 Male | D9: 903 | E9: 798 | F9: 76 | G9: 1 | H9: 8 | I9: 1 | J9: 19 | K9: 903 | L9: 28 | M9: 127 | N9: 509 | O9: 83 | P9: 57 | Q9: 64 | R9: 20 | S9: 8 | T9: 3 | U9: 4 | V9: 903 | W9: 811 | X9: 30 | Y9: 4 | Z9: 16 | AA9: 0 | AB9: 2 | AC9: 6 | AD9: 10 | AE9: 15 | AF9: 9 | AG9: 3977 | AH9: 9 | AI9: 85 | AJ9: 691 | AK9: 513 | AL9: 304 | AM9: 443 | AN9: 398 | AO9: 325 | AP9: 141 | AQ9: 1068
A10: Total | C10: 女 Female | D10: 4139 | E10: 3636 | F10: 332 | G10: 13 | H10: 75 | I10: 0 | J10: 83 | K10: 4139 | L10: 95 | M10: 277 | N10: 1615 | O10: 618 | P10: 491 | Q10: 529 | R10: 323 | S10: 136 | T10: 31 | U10: 24 | V10: 4139 | W10: 3721 | X10: 134 | Y10: 2 | Z10: 134 | AA10: 2 | AB10: 6 | AC10: 16 | AD10: 27 | AE10: 39 | AF10: 58 | AG10: 458 | AH10: 0 | AI10: 23 | AJ10: 292 | AK10: 19 | AL10: 12 | AM10: 19 | AN10: 11 | AO10: 8 | AP10: 5 | AQ10: 69
C11: 其他 Other | D11: 2 | E11: 2 | F11: 0 | G11: 0 | H11: 0 | I11: 0 | J11: 0 | K11: 2 | L11: 0 | M11: 0 | N11: 0 | O11: 1 | P11: 0 | Q11: 1 | R11: 0 | S11: 0 | T11: 0 | U11: 0 | V11: 2 | W11: 1 | X11: 0 | Y11: 0 | Z11: 0 | AA11: 0 | AB11: 0 | AC11: 0 | AD11: 0 | AE11: 1 | AF11: 0 | AG11: 0 | AH11: 0 | AI11: 0 | AJ11: 0 | AK11: 0 | AL11: 0 | AM11: 0 | AN11: 0 | AO11: 0 | AP11: 0 | AQ11: 0
C12: 不詳Unknown | D12: 16 | E12: 8 | F12: 1 | G12: 0 | H12: 0 | I12: 0 | J12: 7 | K12: 16 | L12: 0 | M12: 1 | N12: 11 | O12: 0 | P12: 1 | Q12: 0 | R12: 0 | S12: 0 | T12: 0 | U12: 3 | V12: 16 | W12: 11 | X12: 0 | Y12: 0 | Z12: 0 | AA12: 0 | AB12: 0 | AC12: 0 | AD12: 0 | AE12: 1 | AF12: 4 | AG12: 136 | AH12: 0 | AI12: 0 | AJ12: 6 | AK12: 1 | AL12: 0 | AM12: 0 | AN12: 2 | AO12: 0 | AP12: 0 | AQ12: 127
A13: 新北市 | C13: 計 Total | D13: 954 | E13: 866 | F13: 36 | G13: 1 | H13: 11 | I13: 1 | J13: 39 | K13: 954 | L13: 24 | M13: 80 | N13: 431 | O13: 118 | P13: 101 | Q13: 108 | R13: 52 | S13: 19 | T13: 9 | U13: 12 | V13: 954 | W13: 849 | X13: 26 | Y13: 1 | Z13: 30 | AA13: 1 | AB13: 2 | AC13: 4 | AD13: 8 | AE13: 14 | AF13: 19 | AG13: 879 | AH13: 4 | AI13: 23 | AJ13: 194 | AK13: 86 | AL13: 43 | AM13: 83 | AN13: 69 | AO13: 52 | AP13: 32 | AQ13: 293
C14: 男 Male | D14: 167 | E14: 148 | F14: 10 | G14: 0 | H14: 1 | I14: 1 | J14: 7 | K14: 167 | L14: 5 | M14: 19 | N14: 100 | O14: 15 | P14: 10 | Q14: 8 | R14: 6 | S14: 1 | T14: 1 | U14: 2 | V14: 167 | W14: 146 | X14: 7 | Y14: 1 | Z14: 2 | AA14: 0 | AB14: 0 | AC14: 0 | AD14: 2 | AE14: 5 | AF14: 4 | AG14: 754 | AH14: 4 | AI14: 17 | AJ14: 130 | AK14: 82 | AL14: 42 | AM14: 81 | AN14: 65 | AO14: 52 | AP14: 30 | AQ14: 251
A15: New Taipei City | C15: 女 Female | D15: 783 | E15: 714 | F15: 26 | G15: 1 | H15: 10 | I15: 0 | J15: 32 | K15: 783 | L15: 19 | M15: 61 | N15: 329 | O15: 102 | P15: 91 | Q15: 99 | R15: 46 | S15: 18 | T15: 8 | U15: 10 | V15: 783 | W15: 700 | X15: 19 | Y15: 0 | Z15: 28 | AA15: 1 | AB15: 2 | AC15: 4 | AD15: 6 | AE15: 8 | AF15: 15 | AG15: 102 | AH15: 0 | AI15: 6 | AJ15: 63 | AK15: 4 | AL15: 1 | AM15: 2 | AN15: 4 | AO15: 0 | AP15: 2 | AQ15: 20
C16: 其他 Other | D16: 2 | E16: 2 | F16: 0 | G16: 0 | H16: 0 | I16: 0 | J16: 0 | K16: 2 | L16: 0 | M16: 0 | N16: 0 | O16: 1 | P16: 0 | Q16: 1 | R16: 0 | S16: 0 | T16: 0 | U16: 0 | V16: 2 | W16: 1 | X16: 0 | Y16: 0 | Z16: 0 | AA16: 0 | AB16: 0 | AC16: 0 | AD16: 0 | AE16: 1 | AF16: 0 | AG16: 0 | AH16: 0 | AI16: 0 | AJ16: 0 | AK16: 0 | AL16: 0 | AM16: 0 | AN16: 0 | AO16: 0 | AP16: 0 | AQ16: 0
C17: 不詳Unknown | D17: 2 | E17: 2 | F17: 0 | G17: 0 | H17: 0 | I17: 0 | J17: 0 | K17: 2 | L17: 0 | M17: 0 | N17: 2 | O17: 0 | P17: 0 | Q17: 0 | R17: 0 | S17: 0 | T17: 0 | U17: 0 | V17: 2 | W17: 2 | X17: 0 | Y17: 0 | Z17: 0 | AA17: 0 | AB17: 0 | AC17: 0 | AD17: 0 | AE17: 0 | AF17: 0 | AG17: 23 | AH17: 0 | AI17: 0 | AJ17: 1 | AK17: 0 | AL17: 0 | AM17: 0 | AN17: 0 | AO17: 0 | AP17: 0 | AQ17: 22
A18: 臺北市 | C18: 計 Total | D18: 523 | E18: 478 | F18: 7 | G18: 1 | H18: 17 | I18: 0 | J18: 20 | K18: 523 | L18: 12 | M18: 41 | N18: 128 | O18: 108 | P18: 79 | Q18: 87 | R18: 41 | S18: 18 | T18: 1 | U18: 8 | V18: 523 | W18: 458 | X18: 7 | Y18: 2 | Z18: 17 | AA18: 0 | AB18: 0 | AC18: 3 | AD18: 4 | AE18: 9 | AF18: 23 | AG18: 399 | AH18: 1 | AI18: 18 | AJ18: 52 | AK18: 39 | AL18: 31 | AM18: 39 | AN18: 31 | AO18: 26 | AP18: 7 | AQ18: 155
C19: 男 Male | D19: 89 | E19: 83 | F19: 0 | G19: 1 | H19: 4 | I19: 0 | J19: 1 | K19: 89 | L19: 2 | M19: 21 | N19: 26 | O19: 12 | P19: 10 | Q19: 14 | R19: 1 | S19: 2 | T19: 0 | U19: 1 | V19: 89 | W19: 77 | X19: 2 | Y19: 1 | Z19: 1 | AA19: 0 | AB19: 0 | AC19: 2 | AD19: 1 | AE19: 2 | AF19: 3 | AG19: 356 | AH19: 1 | AI19: 13 | AJ19: 39 | AK19: 35 | AL19: 29 | AM19: 37 | AN19: 29 | AO19: 25 | AP19: 7 | AQ19: 141
A20: Taipei City | C20: 女 Female | D20: 431 | E20: 394 | F20: 7 | G20: 0 | H20: 13 | I20: 0 | J20: 17 | K20: 431 | L20: 10 | M20: 20 | N20: 102 | O20: 96 | P20: 68 | Q20: 73 | R20: 40 | S20: 16 | T20: 1 | U20: 5 | V20: 431 | W20: 381 | X20: 5 | Y20: 1 | Z20: 16 | AA20: 0 | AB20: 0 | AC20: 1 | AD20: 3 | AE20: 7 | AF20: 17 | AG20: 31 | AH20: 0 | AI20: 5 | AJ20: 13 | AK20: 3 | AL20: 2 | AM20: 2 | AN20: 1 | AO20: 1 | AP20: 0 | AQ20: 4
C21: 其他 Other | D21: 0 | E21: 0 | F21: 0 | G21: 0 | H21: 0 | I21: 0 | J21: 0 | K21: 0 | L21: 0 | M21: 0 | N21: 0 | O21: 0 | P21: 0 | Q21: 0 | R21: 0 | S21: 0 | T21: 0 | U21: 0 | V21: 0 | W21: 0 | X21: 0 | Y21: 0 | Z21: 0 | AA21: 0 | AB21: 0 | AC21: 0 | AD21: 0 | AE21: 0 | AF21: 0 | AG21: 0 | AH21: 0 | AI21: 0 | AJ21: 0 | AK21: 0 | AL21: 0 | AM21: 0 | AN21: 0 | AO21: 0 | AP21: 0 | AQ21: 0
C22: 不詳Unknown | D22: 3 | E22: 1 | F22: 0 | G22: 0 | H22: 0 | I22: 0 | J22: 2 | K22: 3 | L22: 0 | M22: 0 | N22: 0 | O22: 0 | P22: 1 | Q22: 0 | R22: 0 | S22: 0 | T22: 0 | U22: 2 | V22: 3 | W22: 0 | X22: 0 | Y22: 0 | Z22: 0 | AA22: 0 | AB22: 0 | AC22: 0 | AD22: 0 | AE22: 0 | AF22: 3 | AG22: 12 | AH22: 0 | AI22: 0 | AJ22: 0 | AK22: 1 | AL22: 0 | AM22: 0 | AN22: 1 | AO22: 0 | AP22: 0 | AQ22: 10
A23: 桃園市 | C23: 計 Total | D23: 557 | E23: 478 | F23: 59 | G23: 3 | H23: 15 | I23: 0 | J23: 2 | K23: 557 | L23: 9 | M23: 32 | N23: 243 | O23: 81 | P23: 70 | Q23: 65 | R23: 45 | S23: 9 | T23: 3 | U23: 0 | V23: 557 | W23: 512 | X23: 21 | Y23: 0 | Z23: 11 | AA23: 0 | AB23: 3 | AC23: 1 | AD23: 2 | AE23: 3 | AF23: 4 | AG23: 548 | AH23: 1 | AI23: 10 | AJ23: 105 | AK23: 65 | AL23: 46 | AM23: 56 | AN23: 48 | AO23: 35 | AP23: 12 | AQ23: 170
C24: 男 Male | D24: 88 | E24: 76 | F24: 11 | G24: 0 | H24: 1 | I24: 0 | J24: 0 | K24: 88 | L24: 3 | M24: 7 | N24: 53 | O24: 12 | P24: 5 | Q24: 6 | R24: 1 | S24: 1 | T24: 0 | U24: 0 | V24: 88 | W24: 81 | X24: 3 | Y24: 0 | Z24: 1 | AA24: 0 | AB24: 1 | AC24: 0 | AD24: 0 | AE24: 2 | AF24: 0 | AG24: 494 | AH24: 1 | AI24: 9 | AJ24: 79 | AK24: 64 | AL24: 46 | AM24: 54 | AN24: 47 | AO24: 35 | AP24: 11 | AQ24: 148
A25: Taoyuan City | C25: 女 Female | D25: 468 | E25: 401 | F25: 48 | G25: 3 | H25: 14 | I25: 0 | J25: 2 | K25: 468 | L25: 6 | M25: 25 | N25: 189 | O25: 69 | P25: 65 | Q25: 59 | R25: 44 | S25: 8 | T25: 3 | U25: 0 | V25: 468 | W25: 430 | X25: 18 | Y25: 0 | Z25: 10 | AA25: 0 | AB25: 2 | AC25: 1 | AD25: 2 | AE25: 1 | AF25: 4 | AG25: 41 | AH25: 0 | AI25: 1 | AJ25: 26 | AK25: 1 | AL25: 0 | AM25: 2 | AN25: 1 | AO25: 0 | AP25: 1 | AQ25: 9
C26: 其他 Other | D26: 0 | E26: 0 | F26: 0 | G26: 0 | H26: 0 | I26: 0 | J26: 0 | K26: 0 | L26: 0 | M26: 0 | N26: 0 | O26: 0 | P26: 0 | Q26: 0 | R26: 0 | S26: 0 | T26: 0 | U26: 0 | V26: 0 | W26: 0 | X26: 0 | Y26: 0 | Z26: 0 | AA26: 0 | AB26: 0 | AC26: 0 | AD26: 0 | AE26: 0 | AF26: 0 | AG26: 0 | AH26: 0 | AI26: 0 | AJ26: 0 | AK26: 0 | AL26: 0 | AM26: 0 | AN26: 0 | AO26: 0 | AP26: 0 | AQ26: 0
C27: 不詳Unknown | D27: 1 | E27: 1 | F27: 0 | G27: 0 | H27: 0 | I27: 0 | J27: 0 | K27: 1 | L27: 0 | M27: 0 | N27: 1 | O27: 0 | P27: 0 | Q27: 0 | R27: 0 | S27: 0 | T27: 0 | U27: 0 | V27: 1 | W27: 1 | X27: 0 | Y27: 0 | Z27: 0 | AA27: 0 | AB27: 0 | AC27: 0 | AD27: 0 | AE27: 0 | AF27: 0 | AG27: 13 | AH27: 0 | AI27: 0 | AJ27: 0 | AK27: 0 | AL27: 0 | AM27: 0 | AN27: 0 | AO27: 0 | AP27: 0 | AQ27: 13
A28: 臺中市 | C28: 計 Total | D28: 685 | E28: 611 | F28: 38 | G28: 2 | H28: 10 | I28: 0 | J28: 24 | K28: 685 | L28: 15 | M28: 33 | N28: 244 | O28: 119 | P28: 93 | Q28: 102 | R28: 56 | S28: 20 | T28: 1 | U28: 2 | V28: 685 | W28: 616 | X28: 21 | Y28: 0 | Z28: 27 | AA28: 0 | AB28: 1 | AC28: 5 | AD28: 4 | AE28: 4 | AF28: 7 | AG28: 622 | AH28: 0 | AI28: 8 | AJ28: 124 | AK28: 64 | AL28: 48 | AM28: 63 | AN28: 58 | AO28: 46 | AP28: 18 | AQ28: 193
C29: 男 Male | D29: 107 | E29: 94 | F29: 7 | G29: 0 | H29: 0 | I29: 0 | J29: 6 | K29: 107 | L29: 3 | M29: 11 | N29: 62 | O29: 9 | P29: 9 | Q29: 9 | R29: 4 | S29: 0 | T29: 0 | U29: 0 | V29: 107 | W29: 100 | X29: 3 | Y29: 0 | Z29: 2 | AA29: 0 | AB29: 0 | AC29: 1 | AD29: 1 | AE29: 0 | AF29: 0 | AG29: 545 | AH29: 0 | AI29: 6 | AJ29: 92 | AK29: 63 | AL29: 46 | AM29: 61 | AN29: 57 | AO29: 44 | AP29: 17 | AQ29: 159
A30: Taichung City | C30: 女 Female | D30: 571 | E30: 515 | F30: 30 | G30: 2 | H30: 10 | I30: 0 | J30: 14 | K30: 571 | L30: 12 | M30: 22 | N30: 176 | O30: 110 | P30: 84 | Q30: 93 | R30: 52 | S30: 20 | T30: 1 | U30: 1 | V30: 571 | W30: 511 | X30: 18 | Y30: 0 | Z30: 25 | AA30: 0 | AB30: 1 | AC30: 4 | AD30: 3 | AE30: 3 | AF30: 6 | AG30: 48 | AH30: 0 | AI30: 2 | AJ30: 29 | AK30: 1 | AL30: 2 | AM30: 2 | AN30: 1 | AO30: 2 | AP30: 1 | AQ30: 8
C31: 其他 Other | D31: 0 | E31: 0 | F31: 0 | G31: 0 | H31: 0 | I31: 0 | J31: 0 | K31: 0 | L31: 0 | M31: 0 | N31: 0 | O31: 0 | P31: 0 | Q31: 0 | R31: 0 | S31: 0 | T31: 0 | U31: 0 | V31: 0 | W31: 0 | X31: 0 | Y31: 0 | Z31: 0 | AA31: 0 | AB31: 0 | AC31: 0 | AD31: 0 | AE31: 0 | AF31: 0 | AG31: 0 | AH31: 0 | AI31: 0 | AJ31: 0 | AK31: 0 | AL31: 0 | AM31: 0 | AN31: 0 | AO31: 0 | AP31: 0 | AQ31: 0
C32: 不詳Unknown | D32: 7 | E32: 2 | F32: 1 | G32: 0 | H32: 0 | I32: 0 | J32: 4 | K32: 7 | L32: 0 | M32: 0 | N32: 6 | O32: 0 | P32: 0 | Q32: 0 | R32: 0 | S32: 0 | T32: 0 | U32: 1 | V32: 7 | W32: 5 | X32: 0 | Y32: 0 | Z32: 0 | AA32: 0 | AB32: 0 | AC32: 0 | AD32: 0 | AE32: 1 | AF32: 1 | AG32: 29 | AH32: 0 | AI32: 0 | AJ32: 3 | AK32: 0 | AL32: 0 | AM32: 0 | AN32: 0 | AO32: 0 | AP32: 0 | AQ32: 26
